Workbook

Sheet CUENTAS
D1: VALOR DÓLAR | E1: 42
B14: DOLARES A PESOS
A15: VIAJE | B15: =B23*E1 -> 0
A16: NETFLIX | B16: =B24*E1 -> 882
A17: SPOTIFY | B17: =B25*E1 -> 630
B22: DOLARES
A24: NETFLIX | B24: 21
A25: SPOTIFY | B25: 15

Sheet GASTOS CASA 2019
I2: UTE/4 | K2: OSE/3 | M2: ANTEL/3 | O2: NETLIX/4 | Q2: SPOTIFY/4
A3: MES | B3: UTE | C3: OSE | D3: ANTEL | E3: NETFLIX | F3: SPOTIFY | G3: TOTAL | I3: MAMA | J3: PAOLA | K3: MAMA | L3: PAOLA | M3: MAMA | N3: PAOLA | O3: MAMA | P3: PAOLA | Q3: PAOLA | T3: ASADO | U3: pasto | V3: IPTV
A4: ENERO | B4: 5081 | C4: 851 | D4: 1396 | E4: =CUENTAS!B16 -> 882 | F4: =CUENTAS!B17 -> 630 | G4: =SUM(B4:F4) -> 8840 | I4: =B4/4 -> 1270.25 | J4: =B4/4 -> 1270.25 | K4: =C4/3 -> 283.66667 | L4: =C4/3 -> 283.66667 | M4: =D4/3 -> 465.33333 | N4: =D4/3 -> 465.33333 | O4: =E4/4 -> 220.5 | P4: =E4/4 -> 220.5 | Q4: =F4/3 -> 210 | U4: 400 | V4: 500
A5: FEBRERO | B5: 5399 | C5: 851 | D5: 1502 | E5: =CUENTAS!B16 -> 882 | F5: =CUENTAS!B17 -> 630 | G5: =SUM(B5:F5) -> 9264 | I5: =B5/4 -> 1349.75 | J5: =B5/4 -> 1349.75 | K5: =C5/3 -> 283.66667 | L5: =C5/3 -> 283.66667 | M5: =D5/3 -> 500.66667 | N5: =D5/3 -> 500.66667 | O5: =E5/4 -> 220.5 | P5: =E5/4 -> 220.5 | Q5: =F5/3 -> 210
A6: MARZO | B6: 5810 | C6: 1276 | D6: 1556 | E6: =CUENTAS!B16 -> 882 | F6: =CUENTAS!B17 -> 630 | G6: =SUM(B6:F6) -> 10154 | I6: =B6/4 -> 1452.5 | J6: =B6/4 -> 1452.5 | K6: =C6/3 -> 425.33333 | L6: =C6/3 -> 425.33333 | M6: =D6/3 -> 518.66667 | N6: =D6/3 -> 518.66667 | O6: =E6/4 -> 220.5 | P6: =E6/4 -> 220.5 | Q6: =F6/3 -> 210
A7: ABRIL | B7: 4635 | C7: 917 | D7: 1558 | E7: =CUENTAS!B16 -> 882 | F7: =CUENTAS!B17 -> 630 | G7: =SUM(B7:F7) -> 8622 | I7: =B7/4 -> 1158.75 | J7: =B7/4 -> 1158.75 | K7: =C7/3 -> 305.66667 | L7: =C7/3 -> 305.66667 | M7: =D7/3 -> 519.33333 | N7: =D7/3 -> 519.33333 | O7: =E7/4 -> 220.5 | P7: =E7/4 -> 220.5 | Q7: =F7/4 -> 157.5
A8: MAYO | B8: 5383 | C8: 1256 | D8: 1594 | E8: =CUENTAS!B16 -> 882 | F8: =CUENTAS!B17 -> 630 | G8: =SUM(B8:F8) -> 9745 | I8: =B8/4 -> 1345.75 | J8: =B8/4 -> 1345.75 | K8: =C8/3 -> 418.66667 | L8: =C8/3 -> 418.66667 | M8: =D8/3 -> 531.33333 | N8: =D8/3 -> 531.33333 | O8: =E8/4 -> 220.5 | P8: =E8/4 -> 220.5 | Q8: =F8/4 -> 157.5
A9: JUNIO | B9: 5267 | C9: 917 | D9: 1552 | E9: =CUENTAS!B16 -> 882 | F9: =CUENTAS!B17 -> 630 | G9: =SUM(B9:F9) -> 9248 | I9: =B9/4 -> 1316.75 | J9: =B9/4 -> 1316.75 | K9: =C9/3 -> 305.66667 | L9: =C9/3 -> 305.66667 | M9: =D9/3 -> 517.33333 | N9: =D9/3 -> 517.33333 | O9: =E9/4 -> 220.5 | P9: =E9/4 -> 220.5 | Q9: =F9/4 -> 157.5 | T9: RAQUEL | V9: TOTAL RECUPERO
A10: JULIO | B10: 5525 | C10: 917 | D10: 1550 | E10: =CUENTAS!B16 -> 882 | F10: =CUENTAS!B17 -> 630 | G10: =SUM(B10:F10) -> 9504 | I10: =B10/4 -> 1381.25 | J10: =B10/4 -> 1381.25 | K10: =C10/3 -> 305.66667 | L10: =C10/3 -> 305.66667 | M10: =D10/3 -> 516.66667 | N10: =D10/3 -> 516.66667 | O10: =E10/4 -> 220.5 | P10: =E10/4 -> 220.5 | Q10: =F10/4 -> 157.5 | S10: NOVIEMBRE | T10: =SUM(I14,K14,M14) -> 1572.45 | U10: 1 | V10: =SUM(B23,G23) -> 6506.5
A11: AGOSTO | B11: 6082 | C11: 917 | D11: 1526 | E11: =CUENTAS!B16 -> 882 | F11: =CUENTAS!B17 -> 630 | G11: =SUM(B11:F11) -> 10037 | I11: =B11/4 -> 1520.5 | J11: =B11/4 -> 1520.5 | K11: =C11/3 -> 305.66667 | L11: =C11/3 -> 305.66667 | M11: =D11/3 -> 508.66667 | N11: =D11/3 -> 508.66667 | O11: =E11/4 -> 220.5 | P11: =E11/4 -> 220.5 | Q11: =F11/4 -> 157.5 | S11: DICIEMBRE | T11: =SUM(I15,K15,M15) -> 1589 | U11: 2 | V11: =SUM(B24,G24) -> 5443.5
A12: SEPTIEMBRE | B12: 6460 | C12: 917 | D12: 1543 | E12: =CUENTAS!B16 -> 882 | F12: =CUENTAS!B17 -> 630 | G12: =SUM(B12:F12) -> 10432 | I12: =B12/4 -> 1615 | J12: =B12/4 -> 1615 | K12: =C12/3 -> 305.66667 | L12: =C12/3 -> 305.66667 | M12: =D12/3 -> 514.33333 | N12: =D12/3 -> 514.33333 | O12: =E12/4 -> 220.5 | P12: =E12/4 -> 220.5 | Q12: =F12/4 -> 157.5 | U12: 3 | V12: =SUM(B25,G25) -> 5968.3333
A13: OCTUBRE | B13: 7262 | C13: 917 | D13: 1558 | E13: =CUENTAS!B16 -> 882 | F13: =CUENTAS!B17 -> 630 | G13: =SUM(B13:F13) -> 11249 | I13: =B13/4 -> 1815.5 | J13: =B13/4 -> 1815.5 | K13: =C13/3 -> 305.66667 | L13: =C13/3 -> 305.66667 | M13: =D13/3 -> 519.33333 | N13: =D13/3 -> 519.33333 | O13: =E13/4 -> 220.5 | P13: =E13/4 -> 220.5 | Q13: =F13/4 -> 157.5 | U13: 4 | V13: =SUM(B26,G26) -> 5090.3333
A14: NOVIEMBRE | B14: 4781 | C14: 917 | D14: 1548 | E14: =CUENTAS!B16 -> 882 | F14: =CUENTAS!B17 -> 630 | G14: =SUM(B14:F14) -> 8758 | I14: =B14/5 -> 956.2 | J14: =B14/5 -> 956.2 | K14: =C14/4 -> 229.25 | L14: =C14/4 -> 229.25 | M14: =D14/4 -> 387 | N14: =D14/4 -> 387 | O14: =E14/4 -> 220.5 | P14: =E14/4 -> 220.5 | Q14: =F14/4 -> 157.5 | U14: 5 | V14: =SUM(B27,G27) -> 5781.3333
A15: DICIEMBRE | B15: 4880 | C15: 917 | D15: 1535 | E15: =CUENTAS!B16 -> 882 | F15: =CUENTAS!B17 -> 630 | G15: =SUM(B15:F15) -> 8844 | I15: =B15/5 -> 976 | J15: =B15/5 -> 976 | K15: =C15/4 -> 229.25 | L15: =C15/4 -> 229.25 | M15: =D15/4 -> 383.75 | N15: =D15/4 -> 383.75 | O15: =E15/4 -> 220.5 | P15: =E15/4 -> 220.5 | Q15: =F15/4 -> 157.5 | U15: 6 | V15: =SUM(B28,G28) -> 5469.3333
A16: ANUAL | B16: =SUM(B4:B15) -> 66565 | C16: =SUM(C4:C15) -> 11570 | D16: =SUM(D4:D15) -> 18418 | E16: =SUM(E4:E15) -> 10584 | F16: =SUM(F4:F15) -> 7560 | G16: =SUM(B16:F16) -> 114697 | U16: 7 | V16: =SUM(B29,G29) -> 5703.6667
U17: 8 | V17: =SUM(B30,G30) -> 5966.1667
U18: 9 | V18: =SUM(B31,G31) -> 6199.8333
U19: 10 | V19: =SUM(B32,G32) -> 7207.8333
U20: 11 | V20: =SUM(B33,G33) -> 4822.4
B21: MAMA | G21: PAOLA | M21: VARIOS | U21: 12 | V21: =SUM(B34,G34) -> 4855.5
A22: MES | C22: DESC | D22: NEGATIVO | F22: MES | H22: DESC | I22: NEGATIVO | K22: MES | L22: EXTRAS | M22: MAMA | N22: PAOLA | R22: CARPA | S22: FIESTAS 12
A23: ENERO | B23: =SUM(I4,K4,M4,O4,M23) -> 2299.75 | D23: =SUM(B23,C23) -> 2299.75 | F23: ENERO | G23: =SUM(J4,L4,N4,P4,Q4,N23,T23,S23,R23) -> 4206.75 | I23: =SUM(G23,H23) -> 4206.75 | K23: ENERO | L23: 180 | M23: =L23/3 -> 60 | N23: =L23/3 -> 60 | Q23: 1 | R23: 31 | S23: 1666 | U23: primero mayo | W23: 1355 mama
A24: FEBRERO | B24: =SUM(I5,K5,M5,O5,M24) -> 2451.25 | D24: =SUM(B24,C24) -> 2451.25 | F24: FEBRERO | G24: =SUM(J5,L5,N5,P5,Q5,N24,T24,S24,R24) -> 2992.25 | I24: =SUM(G24,H24) -> 2992.25 | K24: FEBRERO | L24: 290 | M24: =L24/3 -> 96.666667 | N24: =L24/3 -> 96.666667 | Q24: 2 | R24: 31 | S24: 300 | W24: 3101 pao
A25: MARZO | B25: =SUM(I6,K6,M6,O6,M25) -> 2713.6667 | D25: =SUM(B25,C25) -> 2713.6667 | F25: MARZO | G25: =SUM(J6,L6,N6,P6,Q6,N25,T25,S25,R25) -> 3254.6667 | H25: -300 | I25: =SUM(G25,H25) -> 2954.6667 | K25: MARZO | L25: 290 | M25: =L25/3 -> 96.666667 | N25: =L25/3 -> 96.666667 | Q25: 3 | R25: 31 | S25: 300
A26: ABRIL | B26: =SUM(I7,K7,M7,O7,M26) -> 2300.9167 | D26: =SUM(B26,C26) -> 2300.9167 | F26: ABRIL | G26: =SUM(J7,L7,N7,P7,Q7,N26,T26,S26,R26) -> 2789.4167 | I26: =SUM(G26,H26) -> 2789.4167 | K26: ABRIL | L26: 290 | M26: =L26/3 -> 96.666667 | N26: =L26/3 -> 96.666667 | Q26: 4 | R26: 31 | S26: 300 | U26: 548 | V26: 2/12 parrillero
A27: MAYO | B27: =SUM(I8,K8,M8,O8,M27) -> 2612.9167 | D27: =SUM(B27,C27) -> 2612.9167 | F27: MAYO | G27: =SUM(J8,L8,N8,P8,Q8,N27,T27,S27,R27) -> 3168.4167 | I27: =SUM(G27,H27) -> 3168.4167 | K27: MAYO | L27: 290 | M27: =L27/3 -> 96.666667 | N27: =L27/3 -> 96.666667 | Q27: 5 | R27: 31 | S27: 367 | U27: 49 | V27: 1/12 comida 26/10
A28: JUNIO | B28: =SUM(I9,K9,M9,O9,M28) -> 2456.9167 | D28: =SUM(B28,C28) -> 2456.9167 | F28: JUNIO | G28: =SUM(J9,L9,N9,P9,Q9,N28,T28,S28,R28) -> 3012.4167 | I28: =SUM(G28,H28) -> 3012.4167 | K28: JUNIO | L28: 290 | M28: =L28/3 -> 96.666667 | N28: =L28/3 -> 96.666667 | Q28: 6 | R28: 31 | S28: 367 | U28: 84 | V28: 2/12 comida 23/09
A29: JULIO | B29: =SUM(I10,K10,M10,O10,M29) -> 2574.0833 | D29: =SUM(B29,C29) -> 2574.0833 | F29: JULIO | G29: =SUM(J10,L10,N10,P10,Q10,N29,T29,S29,R29) -> 3129.5833 | I29: =SUM(G29,H29) -> 3129.5833 | K29: JULIO | L29: 450 | M29: =L29/3 -> 150 | N29: =L29/3 -> 150 | Q29: 7 | R29: 31 | S29: 367 | U29: 500 | V29: pasto /4 $125
A30: AGOSTO | B30: =SUM(I11,K11,M11,O11,M30) -> 2705.3333 | D30: =SUM(B30,C30) -> 2705.3333 | F30: AGOSTO | G30: =SUM(J11,L11,N11,P11,Q11,N30,T30,S30,R30) -> 3260.8333 | I30: =SUM(G30,H30) -> 3260.8333 | K30: AGOSTO | L30: 450 | M30: =L30/3 -> 150 | N30: =L30/3 -> 150 | Q30: 8 | R30: 31 | S30: 367
A31: SEPTIEMBRE | B31: =SUM(I12,K12,M12,O12,M31) -> 2822.1667 | D31: =SUM(B31,C31) -> 2822.1667 | F31: SEPTIEMBRE | G31: =SUM(J12,L12,N12,P12,Q12,N31,T31,S31,R31) -> 3377.6667 | I31: =SUM(G31,H31) -> 3377.6667 | K31: SEPTIEMBRE | L31: 500 | M31: =L31/3 -> 166.66667 | N31: =L31/3 -> 166.66667 | Q31: 9 | R31: 31 | S31: 367
A32: OCTUBRE | B32: =SUM(I13,K13,M13,O13,M32) -> 3027.6667 | D32: =SUM(B32,C32) -> 3027.6667 | F32: OCTUBRE | G32: =SUM(J13,L13,N13,P13,Q13,N32,U26,S32,R32,U2,U27) -> 4180.1667 | I32: =SUM(G32,H32) -> 4180.1667 | K32: OCTUBRE | L32: 500 | M32: =L32/3 -> 166.66667 | N32: =L32/3 -> 166.66667 | Q32: 10 | R32: 31 | S32: 367
A33: NOVIEMBRE | B33: =SUM(I14,K14,M14,O14,M33) -> 1792.95 | D33: =SUM(B33,C33) -> 1792.95 | F33: NOVIEMBRE | G33: =SUM(J14,L14,N14,P14,Q14,N33,U28,S33,U26,R33,U27) -> 3029.45 | I33: =SUM(G33,H33) -> 3029.45 | K33: NOVIEMBRE | M33: =L33/5 -> 0 | N33: =L33/5 -> 0 | Q33: 11 | R33: 31 | S33: 367
A34: DICIEMBRE | B34: =SUM(I15,K15,M15,O15,M34) -> 1809.5 | D34: =SUM(B34,C34) -> 1809.5 | F34: DICIEMBRE | G34: =SUM(J15,L15,N15,P15,Q15,N34,U28,S34,U26,R34,U27) -> 3046 | I34: =SUM(G34,H34) -> 3046 | K34: DICIEMBRE | M34: =L34/5 -> 0 | N34: =L34/5 -> 0 | Q34: 12 | R34: 31 | S34: 367
A35: ANUAL | B35: =SUM(B23:B34) -> 29567.117 | D35: =SUM(D23:D34) -> 29567.117 | F35: ANUAL | G35: =SUM(G23:G34) -> 39447.617 | I35: =SUM(I23:I34) -> 39147.617
X39: 256
X40: 20
X41: 17
X42: 151

Sheet GASTOS CASA 2020
I2: UTE/5 | L2: OSE/4 | O2: ANTEL/4 | R2: NETLIX/5 | T2: SPOTIFY/4
A3: MES | B3: UTE | C3: OSE | D3: ANTEL | E3: NETFLIX | F3: SPOTIFY | G3: TOTAL | I3: MAMA | J3: RAQUEL | K3: PAOLA | L3: MAMA | M3: RAQUEL | N3: PAOLA | O3: MAMA | P3: RAQUEL | Q3: PAOLA | R3: MAMA | S3: PAOLA | T3: PAOLA
A4: ENERO | B4: 3527 | C4: 917 | D4: 1581 | E4: =CUENTAS!B16 -> 882 | F4: =CUENTAS!B17 -> 630 | G4: =SUM(B4:F4) -> 7537 | I4: =B4/5 -> 705.4 | J4: =B4/5 -> 705.4 | K4: =B4/5 -> 705.4 | L4: =C4/4 -> 229.25 | M4: =C4/4 -> 229.25 | N4: =C4/4 -> 229.25 | O4: =D4/4 -> 395.25 | P4: =D4/4 -> 395.25 | Q4: =D4/4 -> 395.25 | R4: =E4/4 -> 220.5 | S4: =E4/4 -> 220.5 | T4: =F4/4 -> 157.5
A5: FEBRERO | B5: 4492 | C5: 1256 | D5: 1581 | E5: =CUENTAS!B16 -> 882 | F5: =CUENTAS!B17 -> 630 | G5: =SUM(B5:F5) -> 8841 | I5: =B5/5 -> 898.4 | J5: =B5/5 -> 898.4 | K5: =B5/5 -> 898.4 | L5: =C5/4 -> 314 | M5: =C5/4 -> 314 | N5: =C5/4 -> 314 | O5: =D5/4 -> 395.25 | P5: =D5/4 -> 395.25 | Q5: =D5/4 -> 395.25 | R5: =E5/4 -> 220.5 | S5: =E5/4 -> 220.5 | T5: =F5/4 -> 157.5
A6: MARZO | B6: 4745 | C6: 1256 | D6: 1539 | E6: =CUENTAS!B16 -> 882 | F6: =CUENTAS!B17 -> 630 | G6: =SUM(B6:F6) -> 9052 | I6: =B6/5 -> 949 | J6: =B6/5 -> 949 | K6: =B6/5 -> 949 | L6: =C6/4 -> 314 | M6: =C6/4 -> 314 | N6: =C6/4 -> 314 | O6: =D6/4 -> 384.75 | P6: =D6/4 -> 384.75 | Q6: =D6/4 -> 384.75 | R6: =E6/4 -> 220.5 | S6: =E6/4 -> 220.5 | T6: =F6/4 -> 157.5
A7: ABRIL | B7: 4258 | C7: 917 | D7: 1553 | E7: =CUENTAS!B16 -> 882 | F7: =CUENTAS!B17 -> 630 | G7: =SUM(B7:F7) -> 8240 | I7: =B7/5 -> 851.6 | J7: =B7/5 -> 851.6 | K7: =B7/5 -> 851.6 | L7: =C7/4 -> 229.25 | M7: =C7/4 -> 229.25 | N7: =C7/4 -> 229.25 | O7: =D7/4 -> 388.25 | P7: =D7/4 -> 388.25 | Q7: =D7/4 -> 388.25 | R7: =E7/4 -> 220.5 | S7: =E7/4 -> 220.5 | T7: =F7/4 -> 157.5
A8: MAYO | B8: 5617 | C8: 947 | D8: 1519 | E8: =CUENTAS!B16 -> 882 | F8: =CUENTAS!B17 -> 630 | G8: =SUM(B8:F8) -> 9595 | I8: =B8/5 -> 1123.4 | J8: =B8/5 -> 1123.4 | K8: =B8/5 -> 1123.4 | L8: =C8/4 -> 236.75 | M8: =C8/4 -> 236.75 | N8: =C8/4 -> 236.75 | O8: =D8/4 -> 379.75 | P8: =D8/4 -> 379.75 | Q8: =D8/4 -> 379.75 | R8: =E8/4 -> 220.5 | S8: =E8/4 -> 220.5 | T8: =F8/4 -> 157.5
A9: JUNIO | B9: 6065 | C9: 1015 | D9: 1678 | E9: =CUENTAS!B16 -> 882 | F9: =CUENTAS!B17 -> 630 | G9: =SUM(B9:F9) -> 10270 | I9: =B9/5 -> 1213 | J9: =B9/5 -> 1213 | K9: =B9/5 -> 1213 | L9: =C9/4 -> 253.75 | M9: =C9/4 -> 253.75 | N9: =C9/4 -> 253.75 | O9: =D9/4 -> 419.5 | P9: =D9/4 -> 419.5 | Q9: =D9/4 -> 419.5 | R9: =E9/4 -> 220.5 | S9: =E9/4 -> 220.5 | T9: =F9/4 -> 157.5
A10: JULIO | B10: 5890 | C10: 1015 | D10: 1678 | E10: =CUENTAS!B16 -> 882 | F10: =CUENTAS!B17 -> 630 | G10: =SUM(B10:F10) -> 10095 | I10: 1100 | J10: 1100 | K10: 1230 | L10: =C10/4 -> 253.75 | M10: =C10/4 -> 253.75 | N10: =C10/4 -> 253.75 | O10: =D10/4 -> 419.5 | P10: =D10/4 -> 419.5 | Q10: =D10/4 -> 419.5 | R10: =E10/4 -> 220.5 | S10: =E10/4 -> 220.5 | T10: =F10/4 -> 157.5
A11: AGOSTO | B11: 6107 | C11: 1015 | D11: 1695 | E11: =CUENTAS!B16 -> 882 | F11: =CUENTAS!B17 -> 630 | G11: =SUM(B11:F11) -> 10329 | I11: 1100 | J11: 1100 | K11: 1339 | L11: =C11/4 -> 253.75 | M11: =C11/4 -> 253.75 | N11: =C11/4 -> 253.75 | O11: =D11/4 -> 423.75 | P11: =D11/4 -> 423.75 | Q11: =D11/4 -> 423.75 | R11: =E11/4 -> 220.5 | S11: =E11/4 -> 220.5 | T11: =F11/4 -> 157.5
A12: SEPTIEMBRE | B12: 6445 | C12: 1015 | D12: 1682 | E12: =CUENTAS!B16 -> 882 | F12: =CUENTAS!B17 -> 630 | G12: =SUM(B12:F12) -> 10654 | I12: 1100 | J12: 1100 | K12: =B12/5 -> 1289 | L12: =C12/4 -> 253.75 | M12: =C12/4 -> 253.75 | N12: =C12/4 -> 253.75 | O12: =D12/4 -> 420.5 | P12: =D12/4 -> 420.5 | Q12: =D12/4 -> 420.5 | R12: =E12/4 -> 220.5 | S12: =E12/4 -> 220.5 | T12: =F12/4 -> 157.5
A13: OCTUBRE | B13: 6396 | C13: 1390 | D13: 1690 | E13: =CUENTAS!B16 -> 882 | F13: =CUENTAS!B17 -> 630 | G13: =SUM(B13:F13) -> 10988 | I13: 1100 | J13: 1100 | K13: =B13/5 -> 1279.2 | L13: =C13/4 -> 347.5 | M13: =C13/4 -> 347.5 | N13: =C13/4 -> 347.5 | O13: =D13/4 -> 422.5 | P13: =D13/4 -> 422.5 | Q13: =D13/4 -> 422.5 | R13: =E13/4 -> 220.5 | S13: =E13/4 -> 220.5 | T13: =F13/4 -> 157.5
A14: NOVIEMBRE | B14: 6154 | C14: 1390 | D14: 1684 | E14: =CUENTAS!B16 -> 882 | F14: =CUENTAS!B17 -> 630 | G14: =SUM(B14:F14) -> 10740 | I14: 1100 | J14: 1100 | K14: 1361 | L14: =C14/4 -> 347.5 | M14: =C14/4 -> 347.5 | N14: =C14/4 -> 347.5 | O14: =D14/4 -> 421 | P14: =D14/4 -> 421 | Q14: =D14/4 -> 421 | R14: =E14/4 -> 220.5 | S14: =E14/4 -> 220.5 | T14: =F14/4 -> 157.5
A15: DICIEMBRE | B15: 5899 | C15: 1390 | D15: 1680 | E15: =CUENTAS!B16 -> 882 | F15: =CUENTAS!B17 -> 630 | G15: =SUM(B15:F15) -> 10481 | I15: 1100 | J15: 1100 | K15: =B15/5 -> 1179.8 | L15: =C15/4 -> 347.5 | M15: =C15/4 -> 347.5 | N15: =C15/4 -> 347.5 | O15: =D15/4 -> 420 | P15: =D15/4 -> 420 | Q15: =D15/4 -> 420 | R15: =E15/4 -> 220.5 | S15: =E15/4 -> 220.5 | T15: =F15/4 -> 157.5
A16: ANUAL | B16: =SUM(B4:B15) -> 65595 | C16: =SUM(C4:C15) -> 13523 | D16: =SUM(D4:D15) -> 19560 | E16: =SUM(E4:E15) -> 10584 | F16: =SUM(F4:F15) -> 7560 | G16: =SUM(B16:F16) -> 116822
B21: MAMA | G21: PAOLA | N21: VARIOS | R21: Extras | S21: FIESTAS | T21: Comidas
A22: MES | C22: DESC | D22: NEGATIVO | F22: MES | H22: DESC | I22: NEGATIVO | L22: MES | M22: EXTRAS | N22: MAMA | O22: PAOLA | Q22: 1 | R22: 1065 | S22: 0 | T22: 84
A23: ENERO | B23: =SUM(I4,L4,O4,R4,N23) -> 1550.4 | D23: =SUM(B23,C23) -> 1550.4 | F23: ENERO | G23: =SUM(K4,N4,Q4,S4,T4,O23,S22,R22,T22) -> 2856.9 | I23: =SUM(G23,H23) -> 2856.9 | L23: ENERO | M23: =SUM(H41) -> 0 | N23: 0 | O23: =M23/3 -> 0 | Q23: 2 | R23: 2764 | S23: 0 | T23: 84
A24: FEBRERO | B24: =SUM(I5,L5,O5,R5,N24) -> 1828.15 | D24: =SUM(B24,C24) -> 1828.15 | F24: FEBRERO | G24: =SUM(K5,N5,Q5,S5,T5,O24,S23,R23,T23) -> 4833.65 | I24: =SUM(G24,H24) -> 4833.65 | L24: FEBRERO | M24: =SUM(H41) -> 0 | N24: 0 | O24: =M24/3 -> 0 | Q24: 3 | R24: 2325 | S24: 0 | T24: 84
A25: MARZO | B25: =SUM(I6,L6,O6,R6,N25) -> 1868.25 | D25: =SUM(B25,C25) -> 1868.25 | F25: MARZO | G25: =SUM(K6,N6,Q6,S6,T6,O25,S24,R24,T24) -> 4434.75 | I25: =SUM(G25,H25) -> 4434.75 | L25: MARZO | M25: =SUM(H41) -> 0 | N25: 0 | O25: =M25/3 -> 0 | Q25: 4 | R25: 2325 | S25: 0 | T25: 84
A26: ABRIL | B26: =SUM(I7,L7,O7,R7,N26) -> 1689.6 | D26: =SUM(B26,C26) -> 1689.6 | F26: ABRIL | G26: =SUM(K7,N7,Q7,S7,T7,O26,S25,R25,T25) -> 4256.1 | I26: =SUM(G26,H26) -> 4256.1 | L26: ABRIL | M26: =SUM(H41) -> 0 | N26: 0 | O26: =M26/3 -> 0 | Q26: 5 | R26: 2325 | S26: 0 | T26: 84
A27: MAYO | B27: =SUM(I8,L8,O8,R8,N27) -> 1960.4 | D27: =SUM(B27,C27) -> 1960.4 | F27: MAYO | G27: =SUM(K8,N8,Q8,S8,T8,O27,S26,R26,T26) -> 4526.9 | I27: =SUM(G27,H27) -> 4526.9 | L27: MAYO | M27: =SUM(H41) -> 0 | N27: 0 | O27: =M27/3 -> 0 | Q27: 6 | R27: 2325 | S27: 0 | T27: 84
A28: JUNIO | B28: =SUM(I9,L9,O9,R9,N28) -> 2106.75 | D28: =SUM(B28,C28) -> 2106.75 | F28: JUNIO | G28: =SUM(K9,N9,Q9,S9,T9,O28,S27,R27,T27) -> 4673.25 | I28: =SUM(G28,H28) -> 4673.25 | L28: JUNIO | M28: =SUM(H41) -> 0 | N28: 0 | O28: =M28/3 -> 0 | Q28: 7 | R28: 2325 | S28: 0 | T28: 84
A29: JULIO | B29: =SUM(I10,L10,O10,R10,N29) -> 1993.75 | D29: =SUM(B29,C29) -> 1993.75 | F29: JULIO | G29: =SUM(K10,N10,Q10,S10,T10,O29,S28,R28,T28) -> 4690.25 | I29: =SUM(G29,H29) -> 4690.25 | L29: JULIO | M29: =SUM(H41) -> 0 | N29: 0 | O29: =M29/3 -> 0 | Q29: 8 | R29: 1065 | S29: 0 | T29: 84
A30: AGOSTO | B30: =SUM(I11,L11,O11,R11,N30) -> 2178 | D30: =SUM(B30,C30) -> 2178 | F30: AGOSTO | G30: =SUM(K11,N11,Q11,S11,T11,O30,S29,R29,T29) -> 3543.5 | I30: =SUM(G30,H30) -> 3543.5 | L30: AGOSTO | M30: =SUM(H41) -> 0 | N30: 180 | O30: =M30/3 -> 0 | Q30: 9 | R30: 1065 | S30: 0 | T30: 84
A31: SEPTIEMBRE | B31: =SUM(I12,L12,O12,R12,N31) -> 2174.75 | D31: =SUM(B31,C31) -> 2174.75 | F31: SEPTIEMBRE | G31: =SUM(K12,N12,Q12,S12,T12,O31,S30,R30,T30) -> 3490.25 | I31: =SUM(G31,H31) -> 3490.25 | L31: SEPTIEMBRE | M31: =SUM(H41) -> 0 | N31: 180 | O31: =M31/3 -> 0 | Q31: 10 | R31: 1065 | S31: 0 | T31: 84
A32: OCTUBRE | B32: =SUM(I13,L13,O13,R13,N32) -> 2270.5 | D32: =SUM(B32,C32) -> 2270.5 | F32: OCTUBRE | G32: =SUM(K13,N13,Q13,S13,T13,O32,S31,R31,T31) -> 3576.2 | I32: =SUM(G32,H32) -> 3576.2 | L32: OCTUBRE | M32: =SUM(H41) -> 0 | N32: 180 | O32: =M32/3 -> 0 | Q32: 11 | R32: 417 | S32: 0 | T32: 0
A33: NOVIEMBRE | B33: =SUM(I14,L14,O14,R14,N33) -> 2269 | D33: =SUM(B33,C33) -> 2269 | F33: NOVIEMBRE | G33: =SUM(K14,N14,Q14,S14,T14,O33,S32,R32,T32) -> 2924.5 | I33: =SUM(G33,H33) -> 2924.5 | L33: NOVIEMBRE | M33: =SUM(H41) -> 0 | N33: 180 | O33: =M33/5 -> 0 | Q33: 12 | R33: 417 | S33: 0 | T33: 0
A34: DICIEMBRE | B34: =SUM(I15,L15,O15,R15,N34) -> 2268 | D34: =SUM(B34,C34) -> 2268 | E34: 339 | F34: DICIEMBRE | G34: =SUM(K15,N15,Q15,S15,T15,O34,S33,R33,T33) -> 2742.3 | I34: =SUM(G34,H34) -> 2742.3 | J34: 2887 | L34: DICIEMBRE | M34: =SUM(H41) -> 0 | N34: 180 | O34: =M34/5 -> 0
A35: ANUAL | B35: =SUM(B23:B34) -> 24157.55 | D35: =SUM(D23:D34) -> 24157.55 | F35: ANUAL | G35: =SUM(G23:G34) -> 46548.55 | I35: =SUM(I23:I34) -> 46548.55
B36: 1897
B39: RAQUEL
A40: MES | C40: DESC | D40: NEGATIVO | F40: ASADO | G40: PASTO | H40: IPTV | M40: RECUPERO
A41: ENERO | B41: =SUM(J4,M4,P4) -> 1329.9 | D41: =SUM(B41,C41) -> 1329.9 | G41: 450 | L41: 1 | M41: =SUM(B23,G23) -> 4407.3
A42: FEBRERO | B42: =SUM(J5,M5,P5) -> 1607.65 | D42: =SUM(B42,C42) -> 1607.65 | L42: 2 | M42: =SUM(B24,G24) -> 6661.8
A43: MARZO | B43: =SUM(J6,M6) -> 1263 | D43: =SUM(B43,C43) -> 1263 | L43: 3 | M43: =SUM(B25,G25) -> 6303
A44: ABRIL | B44: =SUM(J7,M7) -> 1080.85 | D44: =SUM(B44,C44) -> 1080.85 | L44: 4 | M44: =SUM(B26,G26) -> 5945.7
A45: MAYO | B45: =SUM(J8,M8) -> 1360.15 | D45: =SUM(B45,C45) -> 1360.15 | L45: 5 | M45: =SUM(B27,G27) -> 6487.3
A46: JUNIO | B46: =SUM(J9,M9) -> 1466.75 | D46: =SUM(B46,C46) -> 1466.75 | L46: 6 | M46: =SUM(B28,G28) -> 6780
A47: JULIO | B47: =SUM(J10,M10) -> 1353.75 | D47: =SUM(B47,C47) -> 1353.75 | L47: 7 | M47: =SUM(B29,G29) -> 6684
...

Sheet GASTOS CASA 2021
I2: UTE/5 | L2: OSE/4 | O2: ANTEL/4 | R2: NETLIX/5 | T2: SPOTIFY/4
A3: MES | B3: UTE | C3: OSE | D3: ANTEL | E3: NETFLIX | F3: SPOTIFY | G3: TOTAL | I3: MAMA | J3: RAQUEL | K3: PAOLA | L3: MAMA | M3: RAQUEL | N3: PAOLA | O3: MAMA | P3: RAQUEL | Q3: PAOLA | R3: MAMA | S3: PAOLA | T3: PAOLA
A4: ENERO | B4: 4924 | C4: 1015 | D4: 1254 | E4: =CUENTAS!B16 -> 882 | F4: =CUENTAS!B17 -> 630 | G4: =SUM(B4:F4) -> 8705 | I4: =B4/5 -> 984.8 | J4: =B4/5 -> 984.8 | K4: =B4/5 -> 984.8 | L4: =C4/4 -> 253.75 | M4: =C4/4 -> 253.75 | N4: =C4/4 -> 253.75 | O4: =D4/4 -> 313.5 | P4: =D4/4 -> 313.5 | Q4: =D4/4 -> 313.5 | R4: =E4/4 -> 220.5 | S4: =E4/4 -> 220.5 | T4: =F4/4 -> 157.5
A5: FEBRERO | B5: 6339 | C5: 1081 | D5: 1657 | E5: =CUENTAS!B16 -> 882 | F5: =CUENTAS!B17 -> 630 | G5: =SUM(B5:F5) -> 10589 | I5: 1100 | J5: 1100 | K5: 1403 | L5: =C5/4 -> 270.25 | M5: =C5/4 -> 270.25 | N5: =C5/4 -> 270.25 | O5: =D5/4 -> 414.25 | P5: =D5/4 -> 414.25 | Q5: =D5/4 -> 414.25 | R5: =E5/4 -> 220.5 | S5: =E5/4 -> 220.5 | T5: =F5/4 -> 157.5
A6: MARZO | B6: 6296 | C6: 1081 | D6: 1867 | E6: =CUENTAS!B16 -> 882 | F6: =CUENTAS!B17 -> 630 | G6: =SUM(B6:F6) -> 10756 | I6: 1100 | J6: 1100 | K6: 1431 | L6: =C6/4 -> 270.25 | M6: =C6/4 -> 270.25 | N6: =C6/4 -> 270.25 | O6: =D6/4 -> 466.75 | P6: =D6/4 -> 466.75 | Q6: =D6/4 -> 466.75 | R6: =E6/4 -> 220.5 | S6: =E6/4 -> 220.5 | T6: =F6/4 -> 157.5
A7: ABRIL | B7: 5580 | C7: 1081 | D7: 1800 | E7: =CUENTAS!B16 -> 882 | F7: =CUENTAS!B17 -> 630 | G7: =SUM(B7:F7) -> 9973 | I7: 1036 | J7: 1036 | K7: 1234 | L7: =C7/4 -> 270.25 | M7: =C7/4 -> 270.25 | N7: =C7/4 -> 270.25 | O7: =D7/4 -> 450 | P7: =D7/4 -> 450 | Q7: =D7/4 -> 450 | R7: =E7/4 -> 220.5 | S7: =E7/4 -> 220.5 | T7: =F7/4 -> 157.5
A8: MAYO | B8: 6192 | C8: 1481 | D8: 1800 | E8: =CUENTAS!B16 -> 882 | F8: =CUENTAS!B17 -> 630 | G8: =SUM(B8:F8) -> 10985 | I8: 1100 | J8: 1100 | K8: 1379 | L8: =C8/4 -> 370.25 | M8: =C8/4 -> 370.25 | N8: =C8/4 -> 370.25 | O8: =D8/4 -> 450 | P8: =D8/4 -> 450 | Q8: =D8/4 -> 450 | R8: =E8/4 -> 220.5 | S8: =E8/4 -> 220.5 | T8: =F8/4 -> 157.5
A9: JUNIO | B9: 6001 | C9: 1081 | D9: 1598 | E9: =CUENTAS!B16 -> 882 | F9: =CUENTAS!B17 -> 630 | G9: =SUM(B9:F9) -> 10192 | I9: 1100 | J9: 1100 | K9: 1283 | L9: =C9/4 -> 270.25 | M9: =C9/4 -> 270.25 | N9: =C9/4 -> 270.25 | O9: =D9/4 -> 399.5 | P9: =D9/4 -> 399.5 | Q9: =D9/4 -> 399.5 | R9: =E9/4 -> 220.5 | S9: =E9/4 -> 220.5 | T9: =F9/4 -> 157.5
A10: JULIO | B10: 7305 | C10: 1081 | D10: 1598 | E10: =CUENTAS!B16 -> 882 | F10: =CUENTAS!B17 -> 630 | G10: =SUM(B10:F10) -> 11496 | I10: 1100 | J10: 1100 | K10: 1935 | L10: =C10/4 -> 270.25 | M10: =C10/4 -> 270.25 | N10: =C10/4 -> 270.25 | O10: =D10/4 -> 399.5 | P10: =D10/4 -> 399.5 | Q10: =D10/4 -> 399.5 | R10: =E10/4 -> 220.5 | S10: =E10/4 -> 220.5 | T10: =F10/4 -> 157.5
A11: AGOSTO | B11: 8047 | C11: 1081 | D11: 1598 | E11: =CUENTAS!B16 -> 882 | F11: =CUENTAS!B17 -> 630 | G11: =SUM(B11:F11) -> 12238 | I11: 1100 | J11: 1100 | K11: 2306 | L11: =C11/4 -> 270.25 | M11: =C11/4 -> 270.25 | N11: =C11/4 -> 270.25 | O11: =D11/4 -> 399.5 | P11: =D11/4 -> 399.5 | Q11: =D11/4 -> 399.5 | R11: =E11/4 -> 220.5 | S11: =E11/4 -> 220.5 | T11: =F11/4 -> 157.5
A12: SEPTIEMBRE | B12: 7707 | C12: 1481 | D12: 1668 | E12: =CUENTAS!B16 -> 882 | F12: =CUENTAS!B17 -> 630 | G12: =SUM(B12:F12) -> 12368 | I12: 1100 | J12: 1100 | K12: 2137 | L12: =C12/4 -> 370.25 | M12: =C12/4 -> 370.25 | N12: =C12/4 -> 370.25 | O12: =D12/4 -> 417 | P12: =D12/4 -> 417 | Q12: =D12/4 -> 417 | R12: =E12/4 -> 220.5 | S12: =E12/4 -> 220.5 | T12: =F12/4 -> 157.5
A13: OCTUBRE | B13: 6892 | C13: 1081 | D13: 1598 | E13: =CUENTAS!B16 -> 882 | F13: =CUENTAS!B17 -> 630 | G13: =SUM(B13:F13) -> 11083 | I13: 1100 | J13: 1100 | K13: 1729 | L13: =C13/4 -> 270.25 | M13: =C13/4 -> 270.25 | N13: =C13/4 -> 270.25 | O13: =D13/4 -> 399.5 | P13: =D13/4 -> 399.5 | Q13: =D13/4 -> 399.5 | R13: =E13/4 -> 220.5 | S13: =E13/4 -> 220.5 | T13: =F13/4 -> 157.5
A14: NOVIEMBRE | B14: 5650 | C14: 1481 | D14: 1598 | E14: =CUENTAS!B16 -> 882 | F14: =CUENTAS!B17 -> 630 | G14: =SUM(B14:F14) -> 10241 | I14: 1090 | J14: 1090 | K14: 1240 | L14: =C14/4 -> 370.25 | M14: =C14/4 -> 370.25 | N14: =C14/4 -> 370.25 | O14: =D14/4 -> 399.5 | P14: =D14/4 -> 399.5 | Q14: =D14/4 -> 399.5 | R14: =E14/4 -> 220.5 | S14: =E14/4 -> 220.5 | T14: =F14/4 -> 157.5
A15: DICIEMBRE | B15: 5182 | C15: 1081 | D15: 1598 | E15: =CUENTAS!B16 -> 882 | F15: =CUENTAS!B17 -> 630 | G15: =SUM(B15:F15) -> 9373 | I15: 1021 | J15: 1021 | K15: 1100 | L15: =C15/4 -> 270.25 | M15: =C15/4 -> 270.25 | N15: =C15/4 -> 270.25 | O15: =D15/4 -> 399.5 | P15: =D15/4 -> 399.5 | Q15: =D15/4 -> 399.5 | R15: =E15/4 -> 220.5 | S15: =E15/4 -> 220.5 | T15: =F15/4 -> 157.5
A16: ANUAL | B16: =SUM(B4:B15) -> 76115 | C16: =SUM(C4:C15) -> 14106 | D16: =SUM(D4:D15) -> 19634 | E16: =SUM(E4:E15) -> 10584 | F16: =SUM(F4:F15) -> 7560 | G16: =SUM(B16:F16) -> 127999
X17: 850 mauro
B21: MAMA | G21: PAOLA | N21: VARIOS | R21: Extras | S21: FIESTAS | T21: Comidas
A22: MES | C22: DESC | D22: NEGATIVO | F22: MES | H22: DESC | I22: NEGATIVO | L22: MES | M22: EXTRAS | N22: MAMA | O22: PAOLA | Q22: 1 | R22: 0 | S22: 0 | T22: 0
A23: ENERO | B23: =SUM(I4,L4,O4,R4,N23) -> 1952.55 | D23: =SUM(B23,C23) -> 1952.55 | F23: ENERO | G23: =SUM(K4,N4,Q4,S4,T4,O23,S22,R22,T22) -> 1930.05 | I23: =SUM(G23,H23) -> 1930.05 | L23: ENERO | M23: =SUM(H41) -> 0 | N23: 180 | O23: =M23/3 -> 0 | Q23: 2 | R23: 120 | S23: 0 | T23: 0
A24: FEBRERO | B24: =SUM(I5,L5,O5,R5,N24) -> 2185 | D24: =SUM(B24,C24) -> 2185 | F24: FEBRERO | G24: =SUM(K5,N5,Q5,S5,T5,O24,S23,R23,T23) -> 2585.5 | I24: =SUM(G24,H24) -> 2585.5 | L24: FEBRERO | M24: =SUM(H41) -> 0 | N24: 180 | O24: =M24/3 -> 0 | Q24: 3 | R24: 4120 | S24: 0 | T24: 0
A25: MARZO | B25: =SUM(I6,L6,O6,R6,N25) -> 2237.5 | D25: =SUM(B25,C25) -> 2237.5 | F25: MARZO | G25: =SUM(K6,N6,Q6,S6,T6,O25,S24,R24,T24) -> 6666 | I25: =SUM(G25,H25) -> 6666 | L25: MARZO | M25: =SUM(H41) -> 0 | N25: 180 | O25: =M25/3 -> 0 | Q25: 4 | R25: 2523 | S25: 0 | T25: 0
A26: ABRIL | B26: =SUM(I7,L7,O7,R7,N26) -> 2156.75 | D26: =SUM(B26,C26) -> 2156.75 | F26: ABRIL | G26: =SUM(K7,N7,Q7,S7,T7,O26,S25,R25,T25) -> 4855.25 | I26: =SUM(G26,H26) -> 4855.25 | L26: ABRIL | M26: =SUM(H41) -> 0 | N26: 180 | O26: =M26/3 -> 0 | Q26: 5 | R26: 2088 | S26: 0 | T26: 0
A27: MAYO | B27: =SUM(I8,L8,O8,R8,N27) -> 2320.75 | D27: =SUM(B27,C27) -> 2320.75 | F27: MAYO | G27: =SUM(K8,N8,Q8,S8,T8,O27,S26,R26,T26) -> 4665.25 | I27: =SUM(G27,H27) -> 4665.25 | L27: MAYO | M27: =SUM(H41) -> 0 | N27: 180 | O27: =M27/3 -> 0 | Q27: 6 | R27: 2662 | S27: 0 | T27: 0
A28: JUNIO | B28: =SUM(I9,L9,O9,R9,N28) -> 1990.25 | D28: =SUM(B28,C28) -> 1990.25 | F28: JUNIO | G28: =SUM(K9,N9,Q9,S9,T9,O28,S27,R27,T27) -> 4992.75 | I28: =SUM(G28,H28) -> 4992.75 | L28: JUNIO | M28: =SUM(H41) -> 0 | N28: 0 | O28: =M28/3 -> 0 | Q28: 7 | R28: 1619 | S28: 0 | T28: 0
A29: JULIO | B29: =SUM(I10,L10,O10,R10,N29) -> 1990.25 | D29: =SUM(B29,C29) -> 1990.25 | F29: JULIO | G29: =SUM(K10,N10,Q10,S10,T10,O29,S28,R28,T28) -> 4601.75 | I29: =SUM(G29,H29) -> 4601.75 | L29: JULIO | M29: =SUM(H41) -> 0 | N29: 0 | O29: =M29/3 -> 0 | Q29: 8 | R29: 1619 | S29: 0 | T29: 0
A30: AGOSTO | B30: =SUM(I11,L11,O11,R11,N30) -> 1990.25 | D30: =SUM(B30,C30) -> 1990.25 | F30: AGOSTO | G30: =SUM(K11,N11,Q11,S11,T11,O30,S29,R29,T29) -> 4972.75 | I30: =SUM(G30,H30) -> 4972.75 | L30: AGOSTO | M30: =SUM(H41) -> 0 | N30: 0 | O30: 0 | Q30: 9 | R30: 1929 | S30: 0 | T30: 0
A31: SEPTIEMBRE | B31: =SUM(I12,L12,O12,R12,N31) -> 3078.75 | D31: =SUM(B31,C31) -> 3078.75 | F31: SEPTIEMBRE | G31: =SUM(K12,N12,Q12,S12,T12,O31,S30,R30,T30) -> 5714.25 | I31: =SUM(G31,H31) -> 5714.25 | L31: SEPTIEMBRE | M31: =SUM(H41) -> 0 | N31: 971 | O31: 483 | Q31: 10 | R31: 1619 | S31: 0 | T31: 0
A32: OCTUBRE | B32: =SUM(I13,L13,O13,R13,N32) -> 2961.25 | D32: =SUM(B32,C32) -> 2961.25 | F32: OCTUBRE | G32: =SUM(K13,N13,Q13,S13,T13,O32,S31,R31,T31) -> 4878.75 | I32: =SUM(G32,H32) -> 4878.75 | L32: OCTUBRE | M32: =SUM(H41) -> 0 | N32: 971 | O32: 483 | Q32: 11 | R32: 1619 | S32: 0 | T32: 0
A33: NOVIEMBRE | B33: =SUM(I14,L14,O14,R14,N33) -> 3051.25 | D33: =SUM(B33,C33) -> 3051.25 | F33: NOVIEMBRE | G33: =SUM(K14,N14,Q14,S14,T14,O33,S32,R32,T32) -> 5551.75 | I33: =SUM(G33,H33) -> 5551.75 | L33: NOVIEMBRE | M33: =SUM(H41) -> 0 | N33: 971 | O33: 1545 | Q33: 12 | R33: 0 | S33: 0 | T33: 0
A34: DICIEMBRE | B34: =SUM(I15,L15,O15,R15,N34) -> 2882.25 | D34: =SUM(B34,C34) -> 2882.25 | F34: DICIEMBRE | G34: =SUM(K15,N15,Q15,S15,T15,O34,S33,R33,T33) -> 3005.75 | I34: =SUM(G34,H34) -> 3005.75 | L34: DICIEMBRE | M34: =SUM(H41) -> 0 | N34: 971 | O34: 858
A35: ANUAL | B35: =SUM(B23:B34) -> 28796.8 | D35: =SUM(D23:D34) -> 28796.8 | F35: ANUAL | G35: =SUM(G23:G34) -> 54419.8 | I35: =SUM(I23:I34) -> 54419.8
B39: RAQUEL
A40: MES | C40: DESC | D40: NEGATIVO | F40: ASADO | G40: PASTO | H40: IPTV | M40: RECUPERO
A41: ENERO | B41: =SUM(J4,M4) -> 1238.55 | D41: =SUM(B41,C41) -> 1238.55 | L41: 1 | M41: =SUM(B23,G23,B41) -> 5121.15
A42: FEBRERO | B42: =SUM(J5,M5) -> 1370.25 | D42: =SUM(B42,C42) -> 1370.25 | L42: 2 | M42: =SUM(B24,G24,B42) -> 6140.75
A43: MARZO | B43: =SUM(J6,M6) -> 1370.25 | D43: =SUM(B43,C43) -> 1370.25 | L43: 3 | M43: =SUM(B25,G25,B43) -> 10273.75
A44: ABRIL | B44: =SUM(J7,M7) -> 1306.25 | D44: =SUM(B44,C44) -> 1306.25 | L44: 4 | M44: =SUM(B26,G26,B44) -> 8318.25
A45: MAYO | B45: =SUM(J8,M8) -> 1470.25 | D45: =SUM(B45,C45) -> 1470.25 | L45: 5 | M45: =SUM(B27,G27,B45) -> 8456.25
A46: JUNIO | B46: =SUM(J9,M9) -> 1370.25 | D46: =SUM(B46,C46) -> 1370.25 | L46: 6 | M46: =SUM(B28,G28,B46) -> 8353.25
A47: JULIO | B47: =SUM(J10,M10) -> 1370.25 | D47: =SUM(B47,C47) -> 1370.25 | L47: 7 | M47: =SUM(B29,G29,B47) -> 7962.25
...

Sheet GASTOS CASA 2022
D1: UTE | E1: 6200
I2: UTE/5 | L2: OSE/4 | O2: ANTEL/4 | R2: NETLIX/5 | T2: SPOTIFY/4
A3: MES | B3: UTE | C3: OSE | D3: ANTEL | E3: NETFLIX | F3: SPOTIFY | G3: TOTAL | I3: MAMA | J3: RAQUEL | K3: PAOLA | L3: MAMA | M3: RAQUEL | N3: PAOLA | O3: MAMA | P3: RAQUEL | Q3: PAOLA | R3: MAMA | S3: PAOLA | T3: PAOLA
A4: ENERO | B4: 4525 | C4: 1081 | D4: 1598 | E4: 762.68 | F4: =CUENTAS!B17 -> 630 | G4: =SUM(B4:F4) -> 8596.68 | I4: 889 | J4: 889 | K4: 969 | L4: =C4/4 -> 270.25 | M4: =C4/4 -> 270.25 | N4: =C4/4 -> 270.25 | O4: =D4/4 -> 399.5 | P4: =D4/4 -> 399.5 | Q4: =D4/4 -> 399.5 | R4: =E4/4 -> 190.67 | S4: =E4/4 -> 190.67 | T4: =F4/4 -> 157.5
A5: FEBRERO | B5: 6408 | C5: 1081 | D5: 1598 | E5: 762.68 | F5: =CUENTAS!B17 -> 630 | G5: =SUM(B5:F5) -> 10479.68 | I5: 1100 | J5: 1100 | K5: 1656 | L5: =C5/4 -> 270.25 | M5: =C5/4 -> 270.25 | N5: =C5/4 -> 270.25 | O5: =D5/4 -> 399.5 | P5: =D5/4 -> 399.5 | Q5: =D5/4 -> 399.5 | R5: =E5/4 -> 190.67 | S5: =E5/4 -> 190.67 | T5: =F5/4 -> 157.5
A6: MARZO | B6: 6922 | C6: 1081 | D6: 1598 | E6: 762.68 | F6: =CUENTAS!B17 -> 630 | G6: =SUM(B6:F6) -> 10993.68 | I6: 1140 | J6: 1140 | K6: 1634 | L6: =C6/4 -> 270.25 | M6: =C6/4 -> 270.25 | N6: =C6/4 -> 270.25 | O6: =D6/4 -> 399.5 | P6: =D6/4 -> 399.5 | Q6: =D6/4 -> 399.5 | R6: =E6/4 -> 190.67 | S6: =E6/4 -> 190.67 | T6: =F6/4 -> 157.5
A7: ABRIL | B7: 5721 | C7: 1570 | D7: 1598 | E7: 762.68 | F7: =CUENTAS!B17 -> 630 | G7: =SUM(B7:F7) -> 10281.68 | I7: 1044 | J7: 1044 | K7: 1294 | L7: =C7/4 -> 392.5 | M7: =C7/4 -> 392.5 | N7: =C7/4 -> 392.5 | O7: =D7/4 -> 399.5 | P7: =D7/4 -> 399.5 | Q7: =D7/4 -> 399.5 | R7: =E7/4 -> 190.67 | S7: =E7/4 -> 190.67 | T7: =F7/4 -> 157.5
A8: MAYO | B8: 5628 | C8: 1146 | D8: 1598 | E8: 762.68 | F8: =CUENTAS!B17 -> 630 | G8: =SUM(B8:F8) -> 9764.68 | I8: 1026 | J8: 1026 | K8: 1276 | L8: =C8/4 -> 286.5 | M8: =C8/4 -> 286.5 | N8: =C8/4 -> 286.5 | O8: =D8/4 -> 399.5 | P8: =D8/4 -> 399.5 | Q8: =D8/4 -> 399.5 | R8: =E8/4 -> 190.67 | S8: =E8/4 -> 190.67 | T8: =F8/4 -> 157.5
A9: JUNIO | B9: 5798 | C9: 1570 | D9: 1598 | E9: 762.68 | F9: =CUENTAS!B17 -> 630 | G9: =SUM(B9:F9) -> 10358.68 | I9: 1059 | J9: 1059 | K9: 1309 | L9: =C9/4 -> 392.5 | M9: =C9/4 -> 392.5 | N9: =C9/4 -> 392.5 | O9: =D9/4 -> 399.5 | P9: =D9/4 -> 399.5 | Q9: =D9/4 -> 399.5 | R9: =E9/4 -> 190.67 | S9: =E9/4 -> 190.67 | T9: =F9/4 -> 157.5
A10: JULIO | B10: 7479 | C10: 1146 | D10: 1598 | E10: 762.68 | F10: =CUENTAS!B17 -> 630 | G10: =SUM(B10:F10) -> 11615.68 | I10: 1140 | J10: 1140 | K10: 1947 | L10: =C10/4 -> 286.5 | M10: =C10/4 -> 286.5 | N10: =C10/4 -> 286.5 | O10: =D10/4 -> 399.5 | P10: =D10/4 -> 399.5 | Q10: =D10/4 -> 399.5 | R10: =E10/4 -> 190.67 | S10: =E10/4 -> 190.67 | T10: =F10/4 -> 157.5
A11: AGOSTO | B11: 7734 | C11: 1146 | D11: 1598 | E11: 762.68 | F11: =CUENTAS!B17 -> 630 | G11: =SUM(B11:F11) -> 11870.68 | I11: 1140 | J11: 1140 | K11: 2150 | L11: =C11/4 -> 286.5 | M11: =C11/4 -> 286.5 | N11: =C11/4 -> 286.5 | O11: =D11/4 -> 399.5 | P11: =D11/4 -> 399.5 | Q11: =D11/4 -> 399.5 | R11: =E11/4 -> 190.67 | S11: =E11/4 -> 190.67 | T11: =F11/4 -> 157.5
A12: SEPTIEMBRE | B12: 7270 | C12: 1146 | D12: 1598 | E12: 762.68 | F12: =CUENTAS!B17 -> 630 | G12: =SUM(B12:F12) -> 11406.68 | I12: 1140 | J12: 1140 | K12: 2006 | L12: =C12/4 -> 286.5 | M12: =C12/4 -> 286.5 | N12: =C12/4 -> 286.5 | O12: =D12/4 -> 399.5 | P12: =D12/4 -> 399.5 | Q12: =D12/4 -> 399.5 | R12: =E12/4 -> 190.67 | S12: =E12/4 -> 190.67 | T12: =F12/4 -> 157.5
A13: OCTUBRE | B13: 7106 | C13: 1146 | D13: 1598 | E13: 762.68 | F13: =CUENTAS!B17 -> 630 | G13: =SUM(B13:F13) -> 11242.68 | I13: 1140 | J13: 1140 | K13: 2007 | L13: =C13/4 -> 286.5 | M13: =C13/4 -> 286.5 | N13: =C13/4 -> 286.5 | O13: =D13/4 -> 399.5 | P13: =D13/4 -> 399.5 | Q13: =D13/4 -> 399.5 | R13: =E13/4 -> 190.67 | S13: =E13/4 -> 190.67 | T13: =F13/4 -> 157.5
A14: NOVIEMBRE | B14: 6450 | C14: 1146 | D14: 1598 | E14: 762.68 | F14: =CUENTAS!B17 -> 630 | G14: =SUM(B14:F14) -> 10586.68 | I14: 1140 | J14: 1140 | K14: 1482 | L14: =C14/4 -> 286.5 | M14: =C14/4 -> 286.5 | N14: =C14/4 -> 286.5 | O14: =D14/4 -> 399.5 | P14: =D14/4 -> 399.5 | Q14: =D14/4 -> 399.5 | R14: =E14/4 -> 190.67 | S14: =E14/4 -> 190.67 | T14: =F14/4 -> 157.5
A15: DICIEMBRE | B15: 5973 | C15: 1146 | D15: 1598 | E15: 762.68 | F15: =CUENTAS!B17 -> 630 | G15: =SUM(B15:F15) -> 10109.68 | I15: 1094 | J15: 1094 | K15: 1323 | L15: =C15/4 -> 286.5 | M15: =C15/4 -> 286.5 | N15: =C15/4 -> 286.5 | O15: =D15/4 -> 399.5 | P15: =D15/4 -> 399.5 | Q15: =D15/4 -> 399.5 | R15: =E15/4 -> 190.67 | S15: =E15/4 -> 190.67 | T15: =F15/4 -> 157.5
A16: ANUAL | B16: =SUM(B4:B15) -> 77014 | C16: =SUM(C4:C15) -> 14405 | D16: =SUM(D4:D15) -> 19176 | E16: =SUM(E4:E15) -> 9152.16 | F16: =SUM(F4:F15) -> 7560 | G16: =SUM(B16:F16) -> 127307.16
B21: MAMA | G21: PAOLA | N21: VARIOS | R21: Extras | S21: FIESTAS | T21: Comidas
A22: MES | C22: DESC | D22: NEGATIVO | F22: MES | H22: DESC | I22: NEGATIVO | L22: MES | M22: EXTRAS | N22: MAMA | O22: PAOLA | Q22: 1 | R22: 0 | S22: 2326 | T22: 393
A23: ENERO | B23: =SUM(I4,L4,O4,R4,N23) -> 2611.42 | D23: =SUM(B23,C23) -> 2611.42 | F23: ENERO | G23: =SUM(K4,N4,Q4,S4,T4,O23,S22,R22,T22) -> 7682.92 | I23: =SUM(G23,H23) -> 7682.92 | L23: ENERO | M23: =SUM(H41) -> 0 | N23: 862 | O23: 2977 | Q23: 2 | R23: 0 | S23: 2979 | T23: 142
A24: FEBRERO | B24: =SUM(I5,L5,O5,R5,N24) -> 2822.42 | D24: =SUM(B24,C24) -> 2822.42 | F24: FEBRERO | G24: =SUM(K5,N5,Q5,S5,T5,O24,S23,R23,T23) -> 7303.92 | I24: =SUM(G24,H24) -> 7303.92 | L24: FEBRERO | M24: =SUM(H41) -> 0 | N24: 862 | O24: 1509 | Q24: 3 | R24: 0 | S24: 1168 | T24: 142
A25: MARZO | B25: =SUM(I6,L6,O6,R6,N25) -> 2862.42 | D25: =SUM(B25,C25) -> 2862.42 | F25: MARZO | G25: =SUM(K6,N6,Q6,S6,T6,O25,S24,R24,T24) -> 5728.92 | I25: =SUM(G25,H25) -> 5728.92 | L25: MARZO | M25: =SUM(H41) -> 0 | N25: 862 | O25: 1767 | Q25: 4 | R25: 0 | S25: 0 | T25: 0
A26: ABRIL | B26: =SUM(I7,L7,O7,R7,N26) -> 2888.67 | D26: =SUM(B26,C26) -> 2888.67 | F26: ABRIL | G26: =SUM(K7,N7,Q7,S7,T7,O26,S25,R25,T25) -> 4201.17 | I26: =SUM(G26,H26) -> 4201.17 | L26: ABRIL | M26: =SUM(H41) -> 0 | N26: 862 | O26: 1767 | Q26: 5 | R26: 0 | S26: 0 | T26: 0
A27: MAYO | B27: =SUM(I8,L8,O8,R8,N27) -> 2764.67 | D27: =SUM(B27,C27) -> 2764.67 | F27: MAYO | G27: =SUM(K8,N8,Q8,S8,T8,O27,S26,R26,T26) -> 4116.17 | I27: =SUM(G27,H27) -> 4116.17 | L27: MAYO | M27: =SUM(H41) -> 0 | N27: 862 | O27: 1806 | Q27: 6 | R27: 0 | S27: 0 | T27: 0
A28: JUNIO | B28: =SUM(I9,L9,O9,R9,N28) -> 2723.67 | D28: =SUM(B28,C28) -> 2723.67 | F28: JUNIO | G28: =SUM(K9,N9,Q9,S9,T9,O28,S27,R27,T27) -> 4216.17 | I28: =SUM(G28,H28) -> 4216.17 | L28: JUNIO | M28: =SUM(H41) -> 0 | N28: 682 | O28: 1767 | Q28: 7 | R28: 0 | S28: 0 | T28: 0
A29: JULIO | B29: =SUM(I10,L10,O10,R10,N29) -> 2698.67 | D29: =SUM(B29,C29) -> 2698.67 | F29: JULIO | G29: =SUM(K10,N10,Q10,S10,T10,O29,S28,R28,T28) -> 2981.17 | I29: =SUM(G29,H29) -> 2981.17 | L29: JULIO | M29: =SUM(H41) -> 0 | N29: 682 | O29: =M29/3 -> 0 | Q29: 8 | R29: 0 | S29: 0 | T29: 0
A30: AGOSTO | B30: =SUM(I11,L11,O11,R11,N30) -> 2698.67 | D30: =SUM(B30,C30) -> 2698.67 | F30: AGOSTO | G30: =SUM(K11,N11,Q11,S11,T11,O30,S29,R29,T29) -> 3184.17 | I30: =SUM(G30,H30) -> 3184.17 | L30: AGOSTO | M30: =SUM(H41) -> 0 | N30: 682 | O30: 0 | Q30: 9 | R30: 0 | S30: 0 | T30: 0
A31: SEPTIEMBRE | B31: =SUM(I12,L12,O12,R12,N31) -> 2016.67 | D31: =SUM(B31,C31) -> 2016.67 | F31: SEPTIEMBRE | G31: =SUM(K12,N12,Q12,S12,T12,O31,S30,R30,T30) -> 3040.17 | I31: =SUM(G31,H31) -> 3040.17 | L31: SEPTIEMBRE | M31: =SUM(H41) -> 0 | N31: 0 | O31: 0 | Q31: 10 | R31: 0 | S31: 0 | T31: 0
A32: OCTUBRE | B32: =SUM(I13,L13,O13,R13,N32) -> 2016.67 | D32: =SUM(B32,C32) -> 2016.67 | F32: OCTUBRE | G32: =SUM(K13,N13,Q13,S13,T13,O32,S31,R31,T31) -> 3041.17 | I32: =SUM(G32,H32) -> 3041.17 | L32: OCTUBRE | M32: =SUM(H41) -> 0 | N32: 0 | O32: 0 | Q32: 11 | R32: 0 | S32: 0 | T32: 0
A33: NOVIEMBRE | B33: =SUM(I14,L14,O14,R14,N33) -> 2016.67 | D33: =SUM(B33,C33) -> 2016.67 | F33: NOVIEMBRE | G33: =SUM(K14,N14,Q14,S14,T14,O33,S32,R32,T32) -> 2516.17 | I33: =SUM(G33,H33) -> 2516.17 | L33: NOVIEMBRE | M33: =SUM(H41) -> 0 | N33: 0 | O33: 0 | Q33: 12 | R33: 0 | S33: 0 | T33: 0
A34: DICIEMBRE | B34: =SUM(I15,L15,O15,R15,N34) -> 1970.67 | D34: =SUM(B34,C34) -> 1970.67 | F34: DICIEMBRE | G34: =SUM(K15,N15,Q15,S15,T15,O34,S33,R33,T33) -> 2357.17 | I34: =SUM(G34,H34) -> 2357.17 | L34: DICIEMBRE | M34: =SUM(H41) -> 0 | N34: 0 | O34: 0
A35: ANUAL | B35: =SUM(B23:B34) -> 30091.29 | D35: =SUM(D23:D34) -> 30091.29 | F35: ANUAL | G35: =SUM(G23:G34) -> 50369.29 | I35: =SUM(I23:I34) -> 50369.29
B39: RAQUEL
A40: MES | C40: DESC | D40: NEGATIVO | E40: EXTRAS | M40: RECUPERO
A41: ENERO | B41: =SUM(J4,E41,M4,F41,G41) -> 2342.25 | D41: =SUM(B41,C41) -> 2342.25 | E41: 183 | F41: 1000 | L41: 1 | M41: =SUM(B23,G23,B41) -> 12636.59
A42: FEBRERO | B42: =SUM(J5,E42,M5) -> 1553.25 | D42: =SUM(B42,C42) -> 1553.25 | E42: 183 | L42: 2 | M42: =SUM(B24,G24,B42) -> 11679.59
A43: MARZO | B43: =SUM(J6,E43,M6,G43) -> 1593.25 | D43: =SUM(B43,C43) -> 1593.25 | E43: 183 | L43: 3 | M43: =SUM(B25,G25,B43) -> 10184.59
A44: ABRIL | B44: =SUM(J7,E44,M7) -> 1619.5 | D44: =SUM(B44,C44) -> 1619.5 | E44: 183 | L44: 4 | M44: =SUM(B26,G26,B44) -> 8709.34
A45: MAYO | B45: =SUM(J8,E45,M8) -> 1495.5 | D45: =SUM(B45,C45) -> 1495.5 | E45: 183 | L45: 5 | M45: =SUM(B27,G27,B45) -> 8376.34
A46: JUNIO | B46: =SUM(J9,E46,M9) -> 1634.5 | D46: =SUM(B46,C46) -> 1634.5 | E46: 183 | L46: 6 | M46: =SUM(B28,G28,B46) -> 8574.34
A47: JULIO | B47: =SUM(J10,E47,M10) -> 1426.5 | D47: =SUM(B47,C47) -> 1426.5 | L47: 7 | M47: =SUM(B29,G29,B47) -> 7106.34
...

Sheet GASTOS CASA 2023
D1: UTE | E1: 6417
I2: UTE/5 | L2: OSE/4 | O2: ANTEL/4 | R2: NETLIX/5 | T2: SPOTIFY/4
A3: MES | B3: UTE | C3: OSE | D3: ANTEL | E3: NETFLIX | F3: SPOTIFY | G3: TOTAL | I3: MAMA | J3: RAQUEL | K3: PAOLA | L3: MAMA | M3: RAQUEL | N3: PAOLA | O3: MAMA | P3: RAQUEL | Q3: PAOLA | R3: MAMA | S3: PAOLA | T3: PAOLA
A4: ENERO | B4: 5902 | C4: 1146 | D4: 1598 | E4: =CUENTAS!B16 -> 882 | F4: =CUENTAS!B17 -> 630 | G4: =SUM(B4:F4) -> 10158 | I4: 1080 | J4: 1080 | K4: 1309 | L4: =C4/4 -> 286.5 | M4: =C4/4 -> 286.5 | N4: =C4/4 -> 286.5 | O4: =D4/4 -> 399.5 | P4: =D4/4 -> 399.5 | Q4: =D4/4 -> 399.5 | R4: =E4/4 -> 220.5 | S4: =E4/4 -> 220.5 | T4: =F4/4 -> 157.5
A5: FEBRERO | B5: 6568 | C5: 1177 | D5: 1598 | E5: =CUENTAS!B16 -> 882 | F5: =CUENTAS!B17 -> 630 | G5: =SUM(B5:F5) -> 10855 | I5: 1140 | J5: 1140 | K5: 1491 | L5: =C5/4 -> 294.25 | M5: =C5/4 -> 294.25 | N5: =C5/4 -> 294.25 | O5: =D5/4 -> 399.5 | P5: =D5/4 -> 399.5 | Q5: =D5/4 -> 399.5 | R5: =E5/4 -> 220.5 | S5: =E5/4 -> 220.5 | T5: =F5/4 -> 157.5
A6: MARZO | B6: 7560 | C6: 1223 | D6: 1640 | E6: =CUENTAS!B16 -> 882 | F6: =CUENTAS!B17 -> 630 | G6: =SUM(B6:F6) -> 11935 | I6: 1200 | J6: 1200 | K6: 1910 | L6: =C6/4 -> 305.75 | M6: =C6/4 -> 305.75 | N6: =C6/4 -> 305.75 | O6: =D6/4 -> 410 | P6: =D6/4 -> 410 | Q6: =D6/4 -> 410 | R6: =E6/4 -> 220.5 | S6: =E6/4 -> 220.5 | T6: =F6/4 -> 157.5
A7: ABRIL | B7: 6153 | C7: 1223 | D7: 1640 | E7: =CUENTAS!B16 -> 882 | F7: =CUENTAS!B17 -> 630 | G7: =SUM(B7:F7) -> 10528 | I7: 1200 | J7: 1200 | K7: 1284 | L7: =C7/4 -> 305.75 | M7: =C7/4 -> 305.75 | N7: =C7/4 -> 305.75 | O7: =D7/4 -> 410 | P7: =D7/4 -> 410 | Q7: =D7/4 -> 410 | R7: =E7/4 -> 220.5 | S7: =E7/4 -> 220.5 | T7: =F7/4 -> 157.5
A8: MAYO | B8: 6886 | C8: 1223 | D8: 1640 | E8: =CUENTAS!B16 -> 882 | F8: =CUENTAS!B17 -> 630 | G8: =SUM(B8:F8) -> 11261 | I8: 1200 | J8: 1200 | K8: 1574 | L8: =C8/4 -> 305.75 | M8: =C8/4 -> 305.75 | N8: =C8/4 -> 305.75 | O8: =D8/4 -> 410 | P8: =D8/4 -> 410 | Q8: =D8/4 -> 410 | R8: =E8/4 -> 220.5 | S8: =E8/4 -> 220.5 | T8: =F8/4 -> 157.5
A9: JUNIO | B9: 5704 | C9: 1223 | D9: 1640 | E9: =CUENTAS!B16 -> 882 | F9: =CUENTAS!B17 -> 630 | G9: =SUM(B9:F9) -> 10079 | I9: 1000 | J9: 1000 | K9: 1310 | L9: =C9/4 -> 305.75 | M9: =C9/4 -> 305.75 | N9: =C9/4 -> 305.75 | O9: =D9/4 -> 410 | P9: =D9/4 -> 410 | Q9: =D9/4 -> 410 | R9: =E9/4 -> 220.5 | S9: =E9/4 -> 220.5 | T9: =F9/4 -> 157.5
A10: JULIO | B10: 6173 | C10: 1223 | D10: 1640 | E10: =CUENTAS!B16 -> 882 | F10: =CUENTAS!B17 -> 630 | G10: =SUM(B10:F10) -> 10548 | I10: 1100 | J10: 1100 | K10: 1408 | L10: =C10/4 -> 305.75 | M10: =C10/4 -> 305.75 | N10: =C10/4 -> 305.75 | O10: =D10/4 -> 410 | P10: =D10/4 -> 410 | Q10: =D10/4 -> 410 | R10: =E10/4 -> 220.5 | S10: =E10/4 -> 220.5 | T10: =F10/4 -> 157.5
A11: AGOSTO | B11: 7195 | C11: 1223 | D11: 1640 | E11: =CUENTAS!B16 -> 882 | F11: =CUENTAS!B17 -> 630 | G11: =SUM(B11:F11) -> 11570 | I11: 1100 | J11: 1100 | K11: 1794 | L11: =C11/4 -> 305.75 | M11: =C11/4 -> 305.75 | N11: =C11/4 -> 305.75 | O11: =D11/4 -> 410 | P11: =D11/4 -> 410 | Q11: =D11/4 -> 410 | R11: =E11/4 -> 220.5 | S11: =E11/4 -> 220.5 | T11: =F11/4 -> 157.5
A12: SEPTIEMBRE | B12: 7615 | C12: 1223 | D12: 1653 | E12: =CUENTAS!B16 -> 882 | F12: =CUENTAS!B17 -> 630 | G12: =SUM(B12:F12) -> 12003 | I12: 1100 | J12: 1100 | K12: 2005 | L12: =C12/4 -> 305.75 | M12: =C12/4 -> 305.75 | N12: =C12/4 -> 305.75 | O12: =D12/4 -> 413.25 | P12: =D12/4 -> 413.25 | Q12: =D12/4 -> 413.25 | R12: =E12/4 -> 220.5 | S12: =E12/4 -> 220.5 | T12: =F12/4 -> 157.5
A13: OCTUBRE | B13: 6956 | C13: 1223 | D13: 1640 | E13: =CUENTAS!B16 -> 882 | F13: =CUENTAS!B17 -> 630 | G13: =SUM(B13:F13) -> 11331 | I13: 1100 | J13: 1100 | K13: 1676 | L13: =C13/4 -> 305.75 | M13: =C13/4 -> 305.75 | N13: =C13/4 -> 305.75 | O13: =D13/4 -> 410 | P13: =D13/4 -> 410 | Q13: =D13/4 -> 410 | R13: =E13/4 -> 220.5 | S13: =E13/4 -> 220.5 | T13: =F13/4 -> 157.5
A14: NOVIEMBRE | B14: 5789 | C14: 1223 | D14: 1640 | E14: =CUENTAS!B16 -> 882 | F14: =CUENTAS!B17 -> 630 | G14: =SUM(B14:F14) -> 10164 | I14: 1000 | J14: 1000 | K14: 1346 | L14: =C14/4 -> 305.75 | M14: =C14/4 -> 305.75 | N14: =C14/4 -> 305.75 | O14: =D14/4 -> 410 | P14: =D14/4 -> 410 | Q14: =D14/4 -> 410 | R14: =E14/4 -> 220.5 | S14: =E14/4 -> 220.5 | T14: =F14/4 -> 157.5
A15: DICIEMBRE | B15: 6414 | C15: 1223 | D15: 1641 | E15: =CUENTAS!B16 -> 882 | F15: =CUENTAS!B17 -> 630 | G15: =SUM(B15:F15) -> 10790 | I15: 1100 | J15: 1100 | K15: 1488 | L15: =C15/4 -> 305.75 | M15: =C15/4 -> 305.75 | N15: =C15/4 -> 305.75 | O15: =D15/4 -> 410.25 | P15: =D15/4 -> 410.25 | Q15: =D15/4 -> 410.25 | R15: =E15/4 -> 220.5 | S15: =E15/4 -> 220.5 | T15: =F15/4 -> 157.5
A16: ANUAL | B16: =SUM(B4:B15) -> 78915 | C16: =SUM(C4:C15) -> 14553 | D16: =SUM(D4:D15) -> 19610 | E16: =SUM(E4:E15) -> 10584 | F16: =SUM(F4:F15) -> 7560 | G16: =SUM(B16:F16) -> 131222
B21: MAMA | G21: PAOLA | N21: VARIOS | R21: Extras | S21: FIESTAS | T21: Comidas
A22: MES | C22: DESC | D22: NEGATIVO | F22: MES | H22: DESC | I22: NEGATIVO | L22: MES | M22: EXTRAS | N22: MAMA | O22: PAOLA | Q22: 1 | R22: 0 | S22: 0 | T22: 0
A23: ENERO | B23: =SUM(I4,L4,O4,R4,N23) -> 1986.5 | D23: =SUM(B23,C23) -> 1986.5 | F23: ENERO | G23: =SUM(K4,N4,Q4,S4,T4,O23,S22,R22,T22) -> 2373 | I23: =SUM(G23,H23) -> 2373 | L23: ENERO | M23: =SUM(H41) -> 0 | N23: 0 | O23: 0 | Q23: 2 | R23: 0 | S23: 0 | T23: 0
A24: FEBRERO | B24: =SUM(I5,L5,O5,R5,N24) -> 2054.25 | D24: =SUM(B24,C24) -> 2054.25 | F24: FEBRERO | G24: =SUM(K5,N5,Q5,S5,T5,O24,S23,R23,T23) -> 2562.75 | I24: =SUM(G24,H24) -> 2562.75 | L24: FEBRERO | M24: =SUM(H41) -> 0 | N24: 0 | O24: 0 | Q24: 3 | R24: 0 | S24: 0 | T24: 0
A25: MARZO | B25: =SUM(I6,L6,O6,R6,N25) -> 2136.25 | D25: =SUM(B25,C25) -> 2136.25 | F25: MARZO | G25: =SUM(K6,N6,Q6,S6,T6,O25,S24,R24,T24) -> 3003.75 | I25: =SUM(G25,H25) -> 3003.75 | L25: MARZO | M25: =SUM(H41) -> 0 | N25: 0 | O25: 0 | Q25: 4 | R25: 0 | S25: 0 | T25: 0
A26: ABRIL | B26: =SUM(I7,L7,O7,R7,N26) -> 2136.25 | D26: =SUM(B26,C26) -> 2136.25 | F26: ABRIL | G26: =SUM(K7,N7,Q7,S7,T7,O26,S25,R25,T25) -> 2377.75 | I26: =SUM(G26,H26) -> 2377.75 | L26: ABRIL | M26: =SUM(H41) -> 0 | N26: 0 | O26: 0 | Q26: 5 | R26: 0 | S26: 0 | T26: 0
A27: MAYO | B27: =SUM(I8,L8,O8,R8,N27) -> 2136.25 | D27: =SUM(B27,C27) -> 2136.25 | F27: MAYO | G27: =SUM(K8,N8,Q8,S8,T8,O27,S26,R26,T26) -> 2667.75 | I27: =SUM(G27,H27) -> 2667.75 | L27: MAYO | M27: =SUM(H41) -> 0 | N27: 0 | O27: 0 | Q27: 6 | R27: 0 | S27: 0 | T27: 0
A28: JUNIO | B28: =SUM(I9,L9,O9,R9,N28) -> 1936.25 | D28: =SUM(B28,C28) -> 1936.25 | F28: JUNIO | G28: =SUM(K9,N9,Q9,S9,T9,O28,S27,R27,T27) -> 2403.75 | I28: =SUM(G28,H28) -> 2403.75 | L28: JUNIO | M28: =SUM(H41) -> 0 | N28: 0 | O28: 0 | Q28: 7 | R28: 0 | S28: 0 | T28: 0
A29: JULIO | B29: =SUM(I10,L10,O10,R10,N29) -> 2036.25 | D29: =SUM(B29,C29) -> 2036.25 | F29: JULIO | G29: =SUM(K10,N10,Q10,S10,T10,O29,S28,R28,T28) -> 2501.75 | I29: =SUM(G29,H29) -> 2501.75 | L29: JULIO | M29: =SUM(H41) -> 0 | N29: 0 | O29: =M29/3 -> 0 | Q29: 8 | R29: 0 | S29: 0 | T29: 0
A30: AGOSTO | B30: =SUM(I11,L11,O11,R11,N30) -> 2179.25 | D30: =SUM(B30,C30) -> 2179.25 | F30: AGOSTO | G30: =SUM(K11,N11,Q11,S11,T11,O30,S29,R29,T29) -> 2887.75 | I30: =SUM(G30,H30) -> 2887.75 | L30: AGOSTO | M30: =SUM(H41) -> 0 | N30: 143 | O30: 0 | Q30: 9 | R30: 0 | S30: 0 | T30: 0
A31: SEPTIEMBRE | B31: =SUM(I12,L12,O12,R12,N31) -> 2182.5 | D31: =SUM(B31,C31) -> 2182.5 | F31: SEPTIEMBRE | G31: =SUM(K12,N12,Q12,S12,T12,O31,S30,R30,T30) -> 3102 | I31: =SUM(G31,H31) -> 3102 | L31: SEPTIEMBRE | M31: =SUM(H41) -> 0 | N31: 143 | O31: 0 | Q31: 10 | R31: 0 | S31: 0 | T31: 0
A32: OCTUBRE | B32: =SUM(I13,L13,O13,R13,N32) -> 2405.25 | D32: =SUM(B32,C32) -> 2405.25 | F32: OCTUBRE | G32: =SUM(K13,N13,Q13,S13,T13,O32,S31,R31,T31) -> 2995.75 | I32: =SUM(G32,H32) -> 2995.75 | L32: OCTUBRE | M32: =SUM(H41) -> 0 | N32: 369 | O32: 226 | Q32: 11 | R32: 0 | S32: 0 | T32: 0
A33: NOVIEMBRE | B33: =SUM(I14,L14,O14,R14,N33) -> 2079.25 | D33: =SUM(B33,C33) -> 2079.25 | F33: NOVIEMBRE | G33: =SUM(K14,N14,Q14,S14,T14,O33,S32,R32,T32) -> 2439.75 | I33: =SUM(G33,H33) -> 2439.75 | L33: NOVIEMBRE | M33: =SUM(H41) -> 0 | N33: 143 | O33: 0 | Q33: 12 | R33: 0 | S33: 0 | T33: 0
A34: DICIEMBRE | B34: =SUM(I15,L15,O15,R15,N34) -> 2179.5 | D34: =SUM(B34,C34) -> 2179.5 | F34: DICIEMBRE | G34: =SUM(K15,N15,Q15,S15,T15,O34,S33,R33,T33) -> 2582 | I34: =SUM(G34,H34) -> 2582 | L34: DICIEMBRE | M34: =SUM(H41) -> 0 | N34: 143 | O34: 0
A35: ANUAL | B35: =SUM(B23:B34) -> 25447.75 | D35: =SUM(D23:D34) -> 25447.75 | F35: ANUAL | G35: =SUM(G23:G34) -> 31897.75 | I35: =SUM(I23:I34) -> 31897.75
B39: RAQUEL
A40: MES | C40: DESC | D40: NEGATIVO | E40: EXTRAS | M40: RECUPERO
A41: ENERO | B41: =SUM(J4,E41,M4,F41,G41) -> 1564.5 | D41: =SUM(B41,C41) -> 1564.5 | E41: 198 | L41: 1 | M41: =SUM(B23,G23,B41) -> 5924
A42: FEBRERO | B42: =SUM(J5,E42,M5) -> 1632.25 | D42: =SUM(B42,C42) -> 1632.25 | E42: 198 | L42: 2 | M42: =SUM(B24,G24,B42) -> 6249.25
A43: MARZO | B43: =SUM(J6,E43,M6,G43) -> 1703.75 | D43: =SUM(B43,C43) -> 1703.75 | E43: 198 | L43: 3 | M43: =SUM(B25,G25,B43) -> 6843.75
A44: ABRIL | B44: =SUM(J7,E44,M7) -> 1505.75 | D44: =SUM(B44,C44) -> 1505.75 | E44: 0 | L44: 4 | M44: =SUM(B26,G26,B44) -> 6019.75
A45: MAYO | B45: =SUM(J8,E45,M8) -> 1505.75 | D45: =SUM(B45,C45) -> 1505.75 | E45: 0 | L45: 5 | M45: =SUM(B27,G27,B45) -> 6309.75
A46: JUNIO | B46: =SUM(J9,E46,M9) -> 1305.75 | D46: =SUM(B46,C46) -> 1305.75 | E46: 0 | L46: 6 | M46: =SUM(B28,G28,B46) -> 5645.75
A47: JULIO | B47: =SUM(J10,E47,M10) -> 1405.75 | D47: =SUM(B47,C47) -> 1405.75 | L47: 7 | M47: =SUM(B29,G29,B47) -> 5943.75
...

Sheet GASTOS CASA 2024
D1: UTE | E1: 6400
I2: UTE/5 | L2: OSE/4 | O2: ANTEL/4 | R2: NETLIX/5 | T2: SPOTIFY/4
A3: MES | B3: UTE | C3: OSE | D3: ANTEL | E3: NETFLIX | F3: SPOTIFY | G3: TOTAL | I3: MAMA | J3: RAQUEL | K3: PAOLA | L3: MAMA | M3: RAQUEL | N3: PAOLA | O3: MAMA | P3: RAQUEL | Q3: PAOLA | R3: MAMA | S3: PAOLA | T3: PAOLA
A4: ENERO | B4: 5810 | C4: 1223 | D4: 1641 | E4: =CUENTAS!B16 -> 882 | F4: =CUENTAS!B17 -> 630 | G4: =SUM(B4:F4) -> 10186 | I4: 1000 | J4: 1000 | K4: 1354 | L4: =C4/4 -> 305.75 | M4: =C4/4 -> 305.75 | N4: =C4/4 -> 305.75 | O4: =D4/4 -> 410.25 | P4: =D4/4 -> 410.25 | Q4: =D4/4 -> 410.25 | R4: =E4/4 -> 220.5 | S4: =E4/4 -> 220.5 | T4: =F4/4 -> 157.5
A5: FEBRERO | B5: 7492 | C5: 1285 | D5: 1641 | E5: =CUENTAS!B16 -> 882 | F5: =CUENTAS!B17 -> 630 | G5: =SUM(B5:F5) -> 11930 | I5: 1150 | J5: 1150 | K5: 1814 | L5: =C5/4 -> 321.25 | M5: =C5/4 -> 321.25 | N5: =C5/4 -> 321.25 | O5: =D5/4 -> 410.25 | P5: =D5/4 -> 410.25 | Q5: =D5/4 -> 410.25 | R5: =E5/4 -> 220.5 | S5: =E5/4 -> 220.5 | T5: =F5/4 -> 157.5
A6: MARZO | B6: 7948 | C6: 1285 | D6: 1733 | E6: =CUENTAS!B16 -> 882 | F6: =CUENTAS!B17 -> 630 | G6: =SUM(B6:F6) -> 12478 | I6: 1150 | J6: 1150 | K6: 1800 | L6: =C6/4 -> 321.25 | M6: =C6/4 -> 321.25 | N6: =C6/4 -> 321.25 | O6: =D6/4 -> 433.25 | P6: =D6/4 -> 433.25 | Q6: =D6/4 -> 433.25 | R6: =E6/4 -> 220.5 | S6: =E6/4 -> 220.5 | T6: =F6/4 -> 157.5
A7: ABRIL | B7: 7124 | C7: 1290 | D7: 1733 | E7: =CUENTAS!B16 -> 882 | F7: =CUENTAS!B17 -> 630 | G7: =SUM(B7:F7) -> 11659 | I7: 1000 | J7: 1000 | K7: 1791 | L7: =C7/4 -> 322.5 | M7: =C7/4 -> 322.5 | N7: =C7/4 -> 322.5 | O7: =D7/4 -> 433.25 | P7: =D7/4 -> 433.25 | Q7: =D7/4 -> 433.25 | R7: =E7/4 -> 220.5 | S7: =E7/4 -> 220.5 | T7: =F7/4 -> 157.5
A8: MAYO | B8: 6353 | C8: 1290 | D8: 1733 | E8: =CUENTAS!B16 -> 882 | F8: =CUENTAS!B17 -> 630 | G8: =SUM(B8:F8) -> 10888 | I8: 900 | J8: 900 | K8: 1601 | L8: =C8/4 -> 322.5 | M8: =C8/4 -> 322.5 | N8: =C8/4 -> 322.5 | O8: =D8/4 -> 433.25 | P8: =D8/4 -> 433.25 | Q8: =D8/4 -> 433.25 | R8: =E8/4 -> 220.5 | S8: =E8/4 -> 220.5 | T8: =F8/4 -> 157.5
A9: JUNIO | B9: 6929 | C9: 1290 | D9: 1733 | E9: =CUENTAS!B16 -> 882 | F9: =CUENTAS!B17 -> 630 | G9: =SUM(B9:F9) -> 11464 | I9: 1100 | J9: 1100 | K9: 1659 | L9: =C9/4 -> 322.5 | M9: =C9/4 -> 322.5 | N9: =C9/4 -> 322.5 | O9: =D9/4 -> 433.25 | P9: =D9/4 -> 433.25 | Q9: =D9/4 -> 433.25 | R9: =E9/4 -> 220.5 | S9: =E9/4 -> 220.5 | T9: =F9/4 -> 157.5
A10: JULIO | B10: 7713 | C10: 1290 | D10: 1733 | E10: =CUENTAS!B16 -> 882 | F10: =CUENTAS!B17 -> 630 | G10: =SUM(B10:F10) -> 12248 | I10: 1150 | J10: 1150 | K10: 1936 | L10: =C10/4 -> 322.5 | M10: =C10/4 -> 322.5 | N10: =C10/4 -> 322.5 | O10: =D10/4 -> 433.25 | P10: =D10/4 -> 433.25 | Q10: =D10/4 -> 433.25 | R10: =E10/4 -> 220.5 | S10: =E10/4 -> 220.5 | T10: =F10/4 -> 157.5
A11: AGOSTO | B11: 7793 | C11: 1290 | D11: 1733 | E11: =CUENTAS!B16 -> 882 | F11: =CUENTAS!B17 -> 630 | G11: =SUM(B11:F11) -> 12328 | I11: 1150 | J11: 1150 | K11: 2031 | L11: =C11/4 -> 322.5 | M11: =C11/4 -> 322.5 | N11: =C11/4 -> 322.5 | O11: =D11/4 -> 433.25 | P11: =D11/4 -> 433.25 | Q11: =D11/4 -> 433.25 | R11: =E11/4 -> 220.5 | S11: =E11/4 -> 220.5 | T11: =F11/4 -> 157.5
A12: SEPTIEMBRE | B12: 8539 | C12: 1290 | D12: 1733 | E12: =CUENTAS!B16 -> 882 | F12: =CUENTAS!B17 -> 630 | G12: =SUM(B12:F12) -> 13074 | I12: 1150 | J12: 1150 | K12: 2437 | L12: =C12/4 -> 322.5 | M12: =C12/4 -> 322.5 | N12: =C12/4 -> 322.5 | O12: =D12/4 -> 433.25 | P12: =D12/4 -> 433.25 | Q12: =D12/4 -> 433.25 | R12: =E12/4 -> 220.5 | S12: =E12/4 -> 220.5 | T12: =F12/4 -> 157.5
A13: OCTUBRE | B13: 8188 | C13: 1290 | D13: 1639 | E13: =CUENTAS!B16 -> 882 | F13: =CUENTAS!B17 -> 630 | G13: =SUM(B13:F13) -> 12629 | I13: 1150 | J13: 1150 | K13: 2178 | L13: =C13/4 -> 322.5 | M13: =C13/4 -> 322.5 | N13: =C13/4 -> 322.5 | O13: =D13/4 -> 409.75 | P13: =D13/4 -> 409.75 | Q13: =D13/4 -> 409.75 | R13: =E13/4 -> 220.5 | S13: =E13/4 -> 220.5 | T13: =F13/4 -> 157.5
A14: NOVIEMBRE | B14: 6955 | C14: 1290 | D14: 771 | E14: =CUENTAS!B16 -> 882 | F14: =CUENTAS!B17 -> 630 | G14: =SUM(B14:F14) -> 10528 | I14: 1150 | J14: 1150 | K14: 1645 | L14: =C14/4 -> 322.5 | M14: =C14/4 -> 322.5 | N14: =C14/4 -> 322.5 | O14: =D14/4 -> 192.75 | P14: =D14/4 -> 192.75 | Q14: =D14/4 -> 192.75 | R14: =E14/4 -> 220.5 | S14: =E14/4 -> 220.5 | T14: =F14/4 -> 157.5
A15: DICIEMBRE | B15: 7485 | C15: 1290 | D15: 771 | E15: =CUENTAS!B16 -> 882 | F15: =CUENTAS!B17 -> 630 | G15: =SUM(B15:F15) -> 11058 | I15: 1150 | J15: 1150 | K15: 1911 | L15: =C15/4 -> 322.5 | M15: =C15/4 -> 322.5 | N15: =C15/4 -> 322.5 | O15: =D15/4 -> 192.75 | P15: =D15/4 -> 192.75 | Q15: =D15/4 -> 192.75 | R15: =E15/4 -> 220.5 | S15: =E15/4 -> 220.5 | T15: =F15/4 -> 157.5
A16: ANUAL | B16: =SUM(B4:B15) -> 88329 | C16: =SUM(C4:C15) -> 15403 | D16: =SUM(D4:D15) -> 18594 | E16: =SUM(E4:E15) -> 10584 | F16: =SUM(F4:F15) -> 7560 | G16: =SUM(B16:F16) -> 140470
B21: MAMA | G21: PAOLA | N21: VARIOS | R21: Extras | S21: FIESTAS | T21: Comidas
A22: MES | C22: DESC | D22: NEGATIVO | F22: MES | H22: DESC | I22: NEGATIVO | L22: MES | M22: EXTRAS | N22: MAMA | O22: PAOLA | Q22: 1 | R22: 0 | S22: 0 | T22: 0
A23: ENERO | B23: =SUM(I4,L4,O4,R4,N23) -> 2079.5 | D23: =SUM(B23,C23) -> 2079.5 | F23: ENERO | G23: =SUM(K4,N4,Q4,S4,T4,O23,S22,R22,T22) -> 2448 | I23: =SUM(G23,H23) -> 2448 | L23: ENERO | M23: =SUM(H41) -> 0 | N23: 143 | O23: 0 | Q23: 2 | R23: 0 | S23: 0 | T23: 0
A24: FEBRERO | B24: =SUM(I5,L5,O5,R5,N24) -> 2245 | D24: =SUM(B24,C24) -> 2245 | F24: FEBRERO | G24: =SUM(K5,N5,Q5,S5,T5,O24,S23,R23,T23) -> 2923.5 | I24: =SUM(G24,H24) -> 2923.5 | L24: FEBRERO | M24: =SUM(H41) -> 0 | N24: 143 | O24: 0 | Q24: 3 | R24: 0 | S24: 0 | T24: 0
A25: MARZO | B25: =SUM(I6,L6,O6,R6,N25) -> 2268 | D25: =SUM(B25,C25) -> 2268 | F25: MARZO | G25: =SUM(K6,N6,Q6,S6,T6,O25,S24,R24,T24) -> 2932.5 | I25: =SUM(G25,H25) -> 2932.5 | L25: MARZO | M25: =SUM(H41) -> 0 | N25: 143 | O25: 0 | Q25: 4 | R25: 0 | S25: 0 | T25: 0
A26: ABRIL | B26: =SUM(I7,L7,O7,R7,N26) -> 2125.25 | D26: =SUM(B26,C26) -> 2125.25 | F26: ABRIL | G26: =SUM(K7,N7,Q7,S7,T7,O26,S25,R25,T25) -> 2924.75 | I26: =SUM(G26,H26) -> 2924.75 | L26: ABRIL | M26: =SUM(H41) -> 0 | N26: 149 | O26: 0 | Q26: 5 | R26: 0 | S26: 0 | T26: 0
A27: MAYO | B27: =SUM(I8,L8,O8,R8,N27) -> 2025.25 | D27: =SUM(B27,C27) -> 2025.25 | F27: MAYO | G27: =SUM(K8,N8,Q8,S8,T8,O27,S26,R26,T26) -> 2734.75 | I27: =SUM(G27,H27) -> 2734.75 | L27: MAYO | M27: =SUM(H41) -> 0 | N27: 149 | O27: 0 | Q27: 6 | R27: 0 | S27: 0 | T27: 0
A28: JUNIO | B28: =SUM(I9,L9,O9,R9,N28) -> 2235.25 | D28: =SUM(B28,C28) -> 2235.25 | F28: JUNIO | G28: =SUM(K9,N9,Q9,S9,T9,O28,S27,R27,T27) -> 2951.75 | I28: =SUM(G28,H28) -> 2951.75 | L28: JUNIO | M28: =SUM(H41) -> 0 | N28: 159 | O28: 159 | Q28: 7 | R28: 0 | S28: 0 | T28: 0
A29: JULIO | B29: =SUM(I10,L10,O10,R10,N29) -> 2126.25 | D29: =SUM(B29,C29) -> 2126.25 | F29: JULIO | G29: =SUM(K10,N10,Q10,S10,T10,O29,S28,R28,T28) -> 3069.75 | I29: =SUM(G29,H29) -> 3069.75 | L29: JULIO | M29: =SUM(H41) -> 0 | N29: 0 | O29: =M29/3 -> 0 | Q29: 8 | R29: 0 | S29: 0 | T29: 0
A30: AGOSTO | B30: =SUM(I11,L11,O11,R11,N30) -> 2126.25 | D30: =SUM(B30,C30) -> 2126.25 | F30: AGOSTO | G30: =SUM(K11,N11,Q11,S11,T11,O30,S29,R29,T29) -> 3164.75 | I30: =SUM(G30,H30) -> 3164.75 | L30: AGOSTO | M30: =SUM(H41) -> 0 | N30: 0 | O30: 0 | Q30: 9 | R30: 0 | S30: 0 | T30: 0
A31: SEPTIEMBRE | B31: =SUM(I12,L12,O12,R12,N31) -> 2126.25 | D31: =SUM(B31,C31) -> 2126.25 | F31: SEPTIEMBRE | G31: =SUM(K12,N12,Q12,S12,T12,O31,S30,R30,T30) -> 3570.75 | I31: =SUM(G31,H31) -> 3570.75 | L31: SEPTIEMBRE | M31: =SUM(H41) -> 0 | N31: 0 | O31: 0 | Q31: 10 | R31: 0 | S31: 0 | T31: 0
A32: OCTUBRE | B32: =SUM(I13,L13,O13,R13,N32) -> 2102.75 | D32: =SUM(B32,C32) -> 2102.75 | F32: OCTUBRE | G32: =SUM(K13,N13,Q13,S13,T13,O32,S31,R31,T31) -> 3288.25 | I32: =SUM(G32,H32) -> 3288.25 | L32: OCTUBRE | M32: =SUM(H41) -> 0 | N32: 0 | O32: 0 | Q32: 11 | R32: 0 | S32: 0 | T32: 0
A33: NOVIEMBRE | B33: =SUM(I14,L14,O14,R14,N33) -> 1885.75 | D33: =SUM(B33,C33) -> 1885.75 | F33: NOVIEMBRE | G33: =SUM(K14,N14,Q14,S14,T14,O33,S32,R32,T32) -> 2538.25 | I33: =SUM(G33,H33) -> 2538.25 | L33: NOVIEMBRE | M33: =SUM(H41) -> 0 | N33: 0 | O33: 0 | Q33: 12 | R33: 0 | S33: 0 | T33: 0
A34: DICIEMBRE | B34: =SUM(I15,L15,O15,R15,N34) -> 1885.75 | D34: =SUM(B34,C34) -> 1885.75 | F34: DICIEMBRE | G34: =SUM(K15,N15,Q15,S15,T15,O34,S33,R33,T33) -> 2804.25 | I34: =SUM(G34,H34) -> 2804.25 | L34: DICIEMBRE | M34: =SUM(H41) -> 0 | N34: 0 | O34: 0
A35: ANUAL | B35: =SUM(B23:B34) -> 25231.25 | D35: =SUM(D23:D34) -> 25231.25 | F35: ANUAL | G35: =SUM(G23:G34) -> 35351.25 | I35: =SUM(I23:I34) -> 35351.25
U38: Deuda Raquel porton
B39: RAQUEL | U39: 10000 | V39: 1473
A40: MES | C40: DESC | D40: NEGATIVO | E40: EXTRAS | M40: RECUPERO | U40: =U39-V39 -> 8527 | V40: 1473
A41: ENERO | B41: =SUM(J4,E41,M4,F41,G41) -> 1604.75 | D41: =SUM(B41,C41) -> 1604.75 | E41: 299 | L41: 1 | M41: =SUM(B23,G23,B41) -> 6132.25 | U41: 7054 | V41: 1473
A42: FEBRERO | B42: =SUM(J5,E42,M5) -> 1770.25 | D42: =SUM(B42,C42) -> 1770.25 | E42: 299 | L42: 2 | M42: =SUM(B24,G24,B42) -> 6938.75 | U42: 5581 | V42: 1473
A43: MARZO | B43: =SUM(J6,E43,M6,G43) -> 1770.25 | D43: =SUM(B43,C43) -> 1770.25 | E43: 299 | L43: 3 | M43: =SUM(B25,G25,B43) -> 6970.75 | U43: 4108
A44: ABRIL | B44: =SUM(J7,E44,M7) -> 1621.5 | D44: =SUM(B44,C44) -> 1621.5 | E44: 299 | L44: 4 | M44: =SUM(B26,G26,B44) -> 6671.5
A45: MAYO | B45: =SUM(J8,E45,M8) -> 1521.5 | D45: =SUM(B45,C45) -> 1521.5 | E45: 299 | L45: 5 | M45: =SUM(B27,G27,B45) -> 6281.5
A46: JUNIO | B46: =SUM(J9,E46,M9) -> 1422.5 | D46: =SUM(B46,C46) -> 1422.5 | L46: 6 | M46: =SUM(B28,G28,B46) -> 6609.5
...

Sheet GASTOS CASA 2025
D1: UTE | E1: 6600
I2: UTE/5 | L2: OSE/4 | O2: ANTEL/4 | R2: NETLIX/4 | T2: SPOTIFY/4
A3: MES | B3: UTE | C3: OSE | D3: ANTEL | E3: NETFLIX | F3: SPOTIFY | G3: TOTAL | I3: MAMA | J3: RAQUEL | K3: PAOLA | L3: MAMA | M3: RAQUEL | N3: PAOLA | O3: MAMA | P3: RAQUEL | Q3: PAOLA | R3: MAMA | S3: PAOLA | T3: PAOLA
A4: ENERO | B4: 7237 | C4: 1290 | D4: 803 | E4: =CUENTAS!B16 -> 882 | F4: =CUENTAS!B17 -> 630 | G4: =SUM(B4:F4) -> 10842 | I4: 1150 | J4: 1150 | K4: 1786 | L4: =C4/4 -> 322.5 | M4: =C4/4 -> 322.5 | N4: =C4/4 -> 322.5 | O4: =D4/4 -> 200.75 | P4: =D4/4 -> 200.75 | Q4: =D4/4 -> 200.75 | R4: =E4/4 -> 220.5 | S4: =E4/4 -> 220.5 | T4: =F4/4 -> 157.5 | U4: aire $600
A5: FEBRERO | B5: 6593 | C5: 1317 | D5: 1762 | E5: =CUENTAS!B16 -> 882 | F5: =CUENTAS!B17 -> 630 | G5: =SUM(B5:F5) -> 11184 | I5: 1000 | J5: 1000 | K5: 1631 | L5: =C5/4 -> 329.25 | M5: =C5/4 -> 329.25 | N5: =C5/4 -> 329.25 | O5: =D5/4 -> 440.5 | P5: =D5/4 -> 440.5 | Q5: =D5/4 -> 440.5 | R5: =E5/4 -> 220.5 | S5: =E5/4 -> 220.5 | T5: =F5/4 -> 157.5
A6: MARZO | B6: 9723 | C6: 1317 | D6: 1820 | E6: =CUENTAS!B16 -> 882 | F6: =CUENTAS!B17 -> 630 | G6: =SUM(B6:F6) -> 14372 | I6: 1350 | J6: 1350 | K6: 3167 | L6: =C6/4 -> 329.25 | M6: =C6/4 -> 329.25 | N6: =C6/4 -> 329.25 | O6: =D6/4 -> 455 | P6: =D6/4 -> 455 | Q6: =D6/4 -> 455 | R6: =E6/4 -> 220.5 | S6: =E6/4 -> 220.5 | T6: =F6/4 -> 157.5
A7: ABRIL | B7: 8718 | C7: 1519 | D7: 1820 | E7: =CUENTAS!B16 -> 882 | F7: =CUENTAS!B17 -> 630 | G7: =SUM(B7:F7) -> 13569 | I7: 1300 | J7: 1300 | K7: 2704 | L7: =C7/4 -> 379.75 | M7: =C7/4 -> 379.75 | N7: =C7/4 -> 379.75 | O7: =D7/4 -> 455 | P7: =D7/4 -> 455 | Q7: =D7/4 -> 455 | R7: =E7/4 -> 220.5 | S7: =E7/4 -> 220.5 | T7: =F7/4 -> 157.5
